Workbook

Sheet UnterkörperA
E2: Körperkonstitution | O2: Logo
C3: Unterkörper
E4: Größe
C5: NAME | E5: Gewicht
B8: Movement Patterns 1&2
B9: TGU ROLL TO 1-ARM PRESS | E9: FOOT HAND CRAWL | G9: 1KB SUITCASE CARRY | J9: PEZZIBALL SUPPORTED SQUAT - WALL | N9: HIP HINGE WITH STICK | R9: SUPPORTED 1-LEG ISO HINGE
B11: ANKLE ROCKERS WIPERS | E11: 2-LEG TOE STANCE WIDE STAND | G11: ANKLE MARCH | J11: 1-LEG A-SKIP | N11: 2-LEG DROP & CATCH | R11: SQUAT JUMP W/PASSIVE ELASTIC
B12: Level A | G12: Block 1 | X12: Level
G13: Datum 1 | H13: Woche 1 | J13: Datum 2 | L13: Datum 3 | M13: Woche 2 | O13: Datum 4 | Q13: Datum 5 | R13: Woche 3 | T13: Datum 6 | X13: Level A
B14: Explosiv Block | G14: TEMPO | H14: RPE | I14: SxR | J14: GEWICHT | L14: TEMPO | M14: RPE | N14: SxR | O14: GEWICHT | Q14: TEMPO | R14: RPE | S14: SxR | T14: GEWICHT | X14: Level 4
B15: 1 | C15: 2-LEG ROPE SKIPPINGS | G15: EXPL | I15: 3x100 | J15: BW | L15: EXPL | N15: 3x125 | O15: BW | Q15: EXPL | S15: 3x150 | T15: BW | X15: Level 7
B16: 2 | C16: 1/2-KN BASKETBALL SIDE TOSS AND CATCH - PARALLEL | G16: EXPL | I16: 3x5 | L16: EXPL | N16: 3x5 | Q16: EXPL | S16: 3x5
B17: 3 | C17: 1/2-KN BASKETBALL SIDE TOSS AND CATCH - 90° | G17: EXPL | I17: 3x5 | L17: EXPL | N17: 3x5 | Q17: EXPL | S17: 3x5
B19: Kraft Block (UKK) | G19: GEWICHT | H19: RPE | I19: SxR | J19: GEWICHT | L19: =G19 -> GEWICHT | M19: RPE | N19: SxR | O19: GEWICHT | Q19: =L19 -> GEWICHT | R19: RPE | S19: SxR | T19: GEWICHT
B20: 1 | C20: PEZZIBALL SUPPORTED SQUAT - WALL | H20: 8-9 | I20: 1x20 | M20: 8-9 | N20: =I20 -> 1x20 | R20: 8-9 | S20: =N20 -> 1x20
B21: 2 | C21: SUPPORTED 1-LEG ISO HINGE | H21: 8-9 | I21: 1x10/ea | M21: 8-9 | N21: =I21 -> 1x10/ea | R21: 8-9 | S21: =N21 -> 1x10/ea
B22: 3 | C22: DEAD BUG | H22: 8-9 | I22: 1x10ea | M22: 8-9 | N22: =I22 -> 1x10ea | R22: 8-9 | S22: =N22 -> 1x10ea
B23: 4 | C23: HIP HINGE WITH STICK | H23: 8-9 | I23: 1x20 | M23: 8-9 | N23: =I23 -> 1x20 | R23: 8-9 | S23: 1x20
B24: 5 | C24: BW SPLIT SQUAT TO TOUCH GROUND WITH STICK | H24: 8-9 | I24: 1x20 | M24: 8-9 | N24: =I24 -> 1x20 | R24: 8-9 | S24: 1x20
B25: 6 | C25: KN SIDE PLANK | H25: 8-9 | I25: 3x10s/ea | M25: 8-9 | N25: =I25 -> 3x10s/ea | R25: 8-9 | S25: =N25 -> 3x10s/ea
B26: 7 | C26: STEPDOWN SMALL STEPPER | H26: 8-9 | I26: 1x20/ea | M26: 8-9 | N26: =I26 -> 1x20/ea | R26: 8-9 | S26: =N26 -> 1x20/ea
B27: 8 | C27: SPLIT STANCE | H27: 8-9 | I27: 1x30s/ea | M27: 8-9 | N27: =I27 -> 1x30s/ea | R27: 8-9 | S27: =N27 -> 1x30s/ea
B28: 9 | C28: 1/2-KN ANTIROTATION HOLD - BAND | H28: 8-9 | I28: 3x10s/ea | M28: 8-9 | N28: =I28 -> 3x10s/ea | R28: 8-9 | S28: =N28 -> 3x10s/ea
B29: 10 | C29: SUPPORTED LATERAL SPLIT SQUAT WITH TRX | H29: 8-9 | I29: 1x20/ea | M29: 8-9 | N29: =I29 -> 1x20/ea | R29: 8-9 | S29: =I29 -> 1x20/ea
B30: 11 | C30: 2-LEG GLUTE BRIDGE | H30: 8-9 | I30: 1x20 | M30: 8-9 | N30: =I30 -> 1x20 | R30: 8-9 | S30: =N30 -> 1x20
B31: 12 | C31: LYING MINIBAND HIP EXTERNAL ROTATION | H31: 8-9 | I31: 1x20/ea | M31: 8-9 | N31: =I31 -> 1x20/ea | R31: 8-9 | S31: =N31 -> 1x20/ea
B32: 13 | C32: SIDELYING LEG HIP ABDUKTION | H32: 8-9 | I32: 1x20/ea | M32: 8-9 | N32: =I32 -> 1x20/ea | R32: 8-9 | S32: =I32 -> 1x20/ea
B33: 14 | C33: SIDELYING LEG HIP ADDUKTION | H33: 8-9 | I33: 1x20/ea | M33: 8-9 | N33: =I33 -> 1x20/ea | R33: 8-9 | S33: =N33 -> 1x20/ea
B34: 15 | C34: SEATED TIBIA BAND RAISE | H34: 8-9 | I34: 1x20/ea | M34: 8-9 | N34: =I34 -> 1x20/ea | R34: 8-9 | S34: =N34 -> 1x20/ea
B35: 16 | C35: 2-LEG CALF RAISES | H35: 8-9 | I35: 1x20 | M35: 8-9 | N35: =I35 -> 1x20 | R35: 8-9 | S35: =N35 -> 1x20
B36: Halteübungen 1
B37: 17 | C37: ISO HOLD 1-LEG CALF RAISE | H37: 8-9 | I37: 1x30s/ea | M37: 8-9 | N37: =I37 -> 1x30s/ea | R37: 8-9 | S37: =N37 -> 1x30s/ea
B38: 18 | C38: ISO HOLD 1-LEG GLUTE BRIDGE | H38: 8-9 | I38: 1x30s/ea | M38: 8-9 | N38: =I38 -> 1x30s/ea | R38: 8-9 | S38: =N38 -> 1x30s/ea
B39: 19 | C39: ISO HOLD SPLIT SQUAT | H39: 8-9 | I39: 1x30s/ea | M39: 8-9 | N39: =I39 -> 1x30s/ea | R39: 8-9 | S39: =N39 -> 1x30s/ea
V40: 1x20/ea
V41: 1x15s/ea
V42: 2x12s/ea
V43: 1x25s/ea
V44: 1x30s/ea
V45: 1x45s/ea
...

Sheet OberkörperA
E2: Körperkonstitution | O2: Logo
C3: Oberkörper
E4: Größe
C5: NAME | E5: Gewicht
B9: Movement Patterns 1&2
B10: =UnterkörperA!B9 -> TGU ROLL TO 1-ARM PRESS | E10: =UnterkörperA!E9 -> FOOT HAND CRAWL | G10: =UnterkörperA!G9 -> 1KB SUITCASE CARRY | J10: =UnterkörperA!J9 -> PEZZIBALL SUPPORTED SQUAT - WALL | N10: =UnterkörperA!N9 -> HIP HINGE WITH STICK | R10: =UnterkörperA!R9 -> SUPPORTED 1-LEG ISO HINGE
B12: =UnterkörperA!B11 -> ANKLE ROCKERS WIPERS | E12: =UnterkörperA!E11 -> 2-LEG TOE STANCE WIDE STAND | G12: =UnterkörperA!G11 -> ANKLE MARCH | J12: =UnterkörperA!J11 -> 1-LEG A-SKIP | N12: =UnterkörperA!N11 -> 2-LEG DROP & CATCH | R12: =UnterkörperA!R11 -> SQUAT JUMP W/PASSIVE ELASTIC
B13: =UnterkörperA!B12 -> Level A | G13: Block 2
G14: Datum 1 | H14: Woche 1 | J14: Datum 2 | L14: Datum 3 | M14: Woche 2 | O14: Datum 4 | Q14: Datum 5 | R14: Woche 3 | T14: Datum 6
B15: Explosiv Block | G15: TEMPO | H15: RPE | I15: SxR | J15: GEWICHT | L15: TEMPO | M15: RPE | N15: SxR | O15: GEWICHT | Q15: TEMPO | R15: RPE | S15: SxR | T15: GEWICHT
B16: 1 | C16: SQUAT JUMP | G16: EXPL | I16: 3x5 | J16: BW | L16: EXPL | N16: 3x5 | O16: BW | Q16: EXPL | S16: 3x5 | T16: BW
B17: 2 | C17: 1/2-KN MB OVERHEAD THROW WITH PARTNER | G17: EXPL | I17: 3x5 | J17: BB | L17: EXPL | N17: 3x5 | O17: BB | Q17: EXPL | S17: 3x5 | T17: BB
B18: 3 | C18: 1/2-KN MB 2-ARM CHEST PASS WITH PARTNER | G18: EXPL | I18: 3x5 | J18: BB | L18: EXPL | N18: 3x5 | O18: BB | Q18: EXPL | S18: 3x5 | T18: BB
B20: Kraft Block (OKK) | G20: GEWICHT | H20: RPE | I20: SxR | J20: GEWICHT | L20: =G20 -> GEWICHT | M20: RPE | N20: SxR | O20: GEWICHT | Q20: =L20 -> GEWICHT | R20: RPE | S20: SxR | T20: GEWICHT
B21: 1 | C21: 1/2-KN 1-ARM CABLE/BAND PRESS | H21: 8-9 | I21: 1x20/ea | M21: 8-9 | N21: =I21 -> 1x20/ea | R21: 8-9 | S21: =N21 -> 1x20/ea
B22: 2 | C22: 1/2-KN 1-ARM BAND PULLDOWN | H22: 8-9 | I22: 1x20/ea | M22: 8-9 | N22: =I22 -> 1x20/ea | R22: 8-9 | S22: =N22 -> 1x20/ea
B23: 3 | C23: DEAD BUG | H23: 8-9 | I23: 1x10/ea | M23: 8-9 | N23: =I23 -> 1x10/ea | R23: 8-9 | S23: =N23 -> 1x10/ea
B24: 4 | C24: SEATED 1-ARM BAND ROW | H24: 8-9 | I24: 1x20/ea | M24: 8-9 | N24: =I24 -> 1x20/ea | R24: 8-9 | S24: 1x20
B25: 5 | C25: SEATED 1-ARM OVERHEAD PRESS | H25: 8-9 | I25: 1x20/ea | M25: 8-9 | N25: =I25 -> 1x20/ea | R25: 8-9 | S25: 1x20
B26: 6 | C26: KN SIDE PLANK | H26: 8-9 | I26: 3x10s/ea | M26: 8-9 | N26: =I26 -> 3x10s/ea | R26: 8-9 | S26: =N26 -> 3x10s/ea
B27: 7 | C27: STANDING BAND PULL APART | H27: 8-9 | I27: 1x20 | M27: 8-9 | N27: =I27 -> 1x20 | R27: 8-9 | S27: =N27 -> 1x20
B28: 8 | C28: STANDING BAND/CABLE BICEP CURL | H28: 8-9 | I28: 1x20/ea | M28: 8-9 | N28: =I28 -> 1x20/ea | R28: 8-9 | S28: =N28 -> 1x20/ea
B29: 9 | C29: STANDING BAND/CABLE TRICEP CURL | H29: 8-9 | I29: 1x20/ea | M29: 8-9 | N29: =I29 -> 1x20/ea | R29: 8-9 | S29: =N29 -> 1x20/ea
B30: 10 | C30: FOOT HAND CRAWL | H30: 8-9 | I30: 1x10m | M30: 8-9 | N30: 1x12m | R30: 8-9 | S30: 1x15m
B31: 11 | C31: UNDERARM SUPINATION/PRONATION | H31: 8-9 | I31: 1x20/ea | M31: 8-9 | N31: =I31 -> 1x20/ea | R31: 8-9 | S31: =N31 -> 1x20/ea
B32: 12 | C32: TENNISBALL SQUEEZE ORANGE | H32: 8-9 | I32: 1x20/ea | M32: 8-9 | N32: =I32 -> 1x20/ea | R32: 8-9 | S32: =N32 -> 1x20/ea
B33: Halteübungen 2
B34: 13 | C34: ISO HOLD PUSH UP PLANK | H34: 8-9 | I34: 1x30s | M34: 8-9 | N34: 1x30s | R34: 8-9 | S34: 1x30s
B35: 14 | C35: ISO HOLD PULL UP PASSIV LOW | H35: 8-9 | I35: 1x30s | M35: =H35 -> 8-9 | N35: =N36 -> 1x30s | R35: =M35 -> 8-9 | S35: =N35 -> 1x30s
B36: 15 | C36: ISO HOLD PRONE BENCH "T" | H36: 8-9 | I36: 1x30s | M36: 8-9 | N36: 1x30s | R36: 8-9 | S36: 1x30s
B37: 16 | C37: ISO HOLD 1/2 KN 1-ARM LANDMINE OVERHEAD PRESS | H37: 8-9 | I37: 1x30s/ea | M37: 8-9 | N37: =I37 -> 1x30s/ea | R37: 8-9 | S37: =I37 -> 1x30s/ea
V38: 1x15s
V39: 1x20s
V40: 1x25s
V41: 1x30s
V42: 1x45s
V43: 1x60s
V44: 3x10s
V45: 1x20
V46: 1x20/ea
...

Sheet UnterkörperB
E2: Körperkonstitution | O2: Logo
C3: Unterkörper
E4: Größe
C5: NAME | E5: Gewicht
B8: Movement Patterns 1&2
B9: 1-ARM PRESS TO ELBOW | E9: BKWD CRAWL | G9: 1KB 1-ARM RACK CARRY | J9: BW SQUAT TO TOUCH SIT ON BOX | N9: HINGE TO KB TOUCH | R9: SUP 1-LEG ISO HINGE WITH HIP ROTATION
B11: ANKEL ROCKERS ROTATIONS | E11: 2-LEG TOE STANCE CLOSE STAND | G11: ANKLE SKIPS | J11: A-SKIP | N11: 1-LEG DROP & CATCH | R11: CMJ W/PASSIVE ELASTIC
B12: Level B | G12: Block 1
G13: Datum 1 | H13: Woche 1 | J13: Datum 2 | L13: Datum 3 | M13: Woche 2 | O13: Datum 4 | Q13: Datum 5 | R13: Woche 3 | T13: Datum 6
B14: Explosiv Block | G14: TEMPO | H14: RPE | I14: SxR | J14: GEWICHT | L14: TEMPO | M14: RPE | N14: SxR | O14: GEWICHT | Q14: TEMPO | R14: RPE | S14: SxR | T14: GEWICHT
B15: 1 | C15: 1-LEG ROPE SKIPPING | G15: EXPL | I15: 3x25/ea | J15: BW | L15: EXPL | N15: 3x40/ea | O15: BW | Q15: EXPL | S15: 3x60/ea | T15: BW
B16: 2 | C16: 1/2-KN BASKETBALL SIDE TOSS AND CATCH - PARALLEL | G16: EXPL | I16: 3x5 | L16: EXPL | N16: 3x5 | Q16: EXPL | S16: 3x5
B17: 3 | C17: 1/2-KN BASKETBALL SIDE TOSS AND CATCH - 90° | G17: EXPL | I17: 3x5 | L17: EXPL | N17: 3x5 | Q17: EXPL | S17: 3x5
B19: Kraft Block (UKK) | G19: GEWICHT | H19: RPE | I19: SxR | J19: GEWICHT | L19: =G19 -> GEWICHT | M19: RPE | N19: SxR | O19: GEWICHT | Q19: =L19 -> GEWICHT | R19: RPE | S19: SxR | T19: GEWICHT
B20: 1 | C20: BW SQUAT TO TOUCH BOX | H20: 8-9 | I20: 1x20 | M20: 8-9 | N20: =I20 -> 1x20 | R20: 8-9 | S20: =N20 -> 1x20
B21: 2 | C21: SUPPORTED 1-LEG ISO HINGE WITH HIP ROTATION | H21: 8-9 | I21: 1x10/ea | M21: 8-9 | N21: =I21 -> 1x10/ea | R21: 8-9 | S21: =N21 -> 1x10/ea
B22: 3 | C22: PLANK | H22: 8-9 | I22: 3x10s | M22: 8-9 | N22: =I22 -> 3x10s | R22: 8-9 | S22: =N22 -> 3x10s
B23: 4 | C23: HINGE TO KB TOUCH (KB SUMO DEADLIFT) | H23: 8-9 | I23: 1x20 | M23: 8-9 | N23: =I23 -> 1x20 | R23: 8-9 | S23: 1x20
B24: 5 | C24: BW STEP BACK SPLIT SQUAT TO GROUND-STICK | H24: 8-9 | I24: 1x20/ea | M24: 8-9 | N24: =I24 -> 1x20/ea | R24: 8-9 | S24: =I24 -> 1x20/ea
B25: 6 | C25: SIDE PLANK | H25: 8-9 | I25: 3x10s | M25: 8-9 | N25: =I25 -> 3x10s | R25: 8-9 | S25: =N25 -> 3x10s
B26: 7 | C26: STEPDOWN MEDIUM STEPPER | H26: 8-9 | I26: 1x20/ea | M26: 8-9 | N26: =I26 -> 1x20/ea | R26: 8-9 | S26: =N26 -> 1x20/ea
B27: 8 | C27: SPLIT STANCE CLOSED EYES | H27: 8-9 | I27: 1x30s/ea | M27: 8-9 | N27: =I27 -> 1x30s/ea | R27: 8-9 | S27: =N27 -> 1x30s/ea
B28: 9 | C28: 1/2-KN ANTI-ROTATION PRESS | H28: 8-9 | I28: 3x10/ea | M28: 8-9 | N28: =I28 -> 3x10/ea | R28: 8-9 | S28: =N28 -> 3x10/ea
B29: 10 | C29: HEARBEAT LATERAL SPLIT SQUAT WITH PEZZIBALL | H29: 8-9 | I29: 1x20/ea | M29: 8-9 | N29: =I29 -> 1x20/ea | R29: 8-9 | S29: =I29 -> 1x20/ea
B30: 11 | C30: 2-LEG MARCHING GLUTE BRIDGE | H30: 8-9 | I30: 1x20 | M30: 8-9 | N30: =I30 -> 1x20 | R30: 8-9 | S30: =N30 -> 1x20
B31: 12 | C31: SIDELYING MINIBAND HIP EXTERNAL RORATION | H31: 8-9 | I31: 1x20/ea | M31: 8-9 | N31: =I31 -> 1x20/ea | R31: 8-9 | S31: =N31 -> 1x20/ea
B32: 13 | C32: STANDING LEG HIP ABDUKTION | H32: 8-9 | I32: 1x20/ea | M32: 8-9 | N32: 1x12m | R32: 8-9 | S32: 1x15m
B33: 14 | C33: STANDING SIDELYING LEG HIP ADDUKTION | H33: 8-9 | I33: 1x20/ea | M33: 8-9 | N33: =I33 -> 1x20/ea | R33: 8-9 | S33: =N33 -> 1x20/ea
B34: 15 | C34: SEATED TIBIA BAND RAISE | H34: 8-9 | I34: 1x20/ea | M34: 8-9 | N34: =I34 -> 1x20/ea | R34: 8-9 | S34: =N34 -> 1x20/ea
B35: 16 | C35: 1-LEG CALF RAISES | H35: 8-9 | I35: 1x20/ea | M35: 8-9 | N35: =I35 -> 1x20/ea | R35: 8-9 | S35: =N35 -> 1x20/ea
B36: Halteübungen 1
B37: 17 | C37: ISO HOLD 1-LEG CALF RAISE | H37: 8-9 | I37: 1x45s/ea | M37: 8-9 | N37: =I37 -> 1x45s/ea | R37: 8-9 | S37: =I37 -> 1x45s/ea
B38: 18 | C38: ISO HOLD 1-LEG GLUTE BRIDGE | H38: 8-9 | I38: 1x45s/ea | M38: 8-9 | N38: =I38 -> 1x45s/ea | R38: 8-9 | S38: =I38 -> 1x45s/ea
B39: 19 | C39: ISO HOLD SPLIT SQUAT | H39: 8-9 | I39: 1x45s/ea | M39: 8-9 | N39: =I39 -> 1x45s/ea | R39: 8-9 | S39: =N39 -> 1x45s/ea
V41: 1x15s/ea
V42: 2x12s/ea
V43: 1x25s/ea
V44: 1x30s/ea
V45: 1x45s/ea
V46: 1x60s/ea
...

Sheet OberkörperB
E2: Körperkonstitution | O2: Logo
C3: Oberkörper
E4: Größe
C5: NAME | E5: Gewicht
C10: Preparatory | E10: General Preparation | I10: Technical Development | M10: Accumulation | Q10: Dynamic | S10: =UnterkörperA!#REF! -> #REF!
B12: 1-ARM PRESS TO ELBOW | E12: BKWD CRAWL | H12: 1KB 1-ARM RACK CARRY | L12: =UnterkörperB!J9 -> BW SQUAT TO TOUCH SIT ON BOX | O12: =UnterkörperB!N9 -> HINGE TO KB TOUCH | R12: =UnterkörperB!R9 -> SUP 1-LEG ISO HINGE WITH HIP ROTATION
B14: =UnterkörperB!B11 -> ANKEL ROCKERS ROTATIONS | E14: =UnterkörperB!E11 -> 2-LEG TOE STANCE CLOSE STAND | H14: =UnterkörperB!G11 -> ANKLE SKIPS | L14: =UnterkörperB!J11 -> A-SKIP | O14: =UnterkörperB!N11 -> 1-LEG DROP & CATCH | S14: =UnterkörperB!R11 -> CMJ W/PASSIVE ELASTIC
B15: =UnterkörperB!B12 -> Level B | G15: Block 2
G16: Datum 1 | H16: Woche 1 | J16: Datum 2 | L16: Datum 3 | M16: Woche 2 | O16: Datum 4 | Q16: Datum 5 | R16: Woche 3 | T16: Datum 6
B17: Explosiv Block | G17: TEMPO | H17: RPE | I17: SxR | J17: GEWICHT | L17: TEMPO | M17: RPE | N17: SxR | O17: GEWICHT | Q17: TEMPO | R17: RPE | S17: SxR | T17: GEWICHT
B18: 1 | C18: CM JUMP | G18: EXPL | I18: 3x5 | J18: BW | L18: EXPL | N18: 3x5 | O18: BW | Q18: EXPL | S18: 3x5 | T18: BW
B19: 2 | C19: 1/2-KN MB OVERHEAD THROW INTO WALL | G19: EXPL | I19: 3x5 | J19: BB | L19: EXPL | N19: 3x5 | O19: BB | Q19: EXPL | S19: 3x5 | T19: BB
B20: 3 | C20: 1/2-KN MB 2-ARM CHEST PASS INTO WALL | G20: EXPL | I20: 3x5 | J20: BB | L20: EXPL | N20: 3x5 | O20: BB | Q20: EXPL | S20: 3x5 | T20: BB
B22: Kraft Block (OKK) | G22: GEWICHT | H22: RPE | I22: SxR | J22: GEWICHT | L22: =G22 -> GEWICHT | M22: RPE | N22: SxR | O22: GEWICHT | Q22: =L22 -> GEWICHT | R22: RPE | S22: SxR | T22: GEWICHT
B23: 1 | C23: ARMS ELEVATED PUSH UP HIGH | H23: 8-9 | I23: 1x20 | M23: 8-9 | N23: =I23 -> 1x20 | R23: 8-9 | S23: =N23 -> 1x20
B24: 2 | C24: 1/2-KN 1-ARM BAND PULLDOWN | H24: 8-9 | I24: 1x20 | M24: 8-9 | N24: =I24 -> 1x20 | R24: 8-9 | S24: =N24 -> 1x20
B25: 3 | C25: PLANK | H25: 8-9 | I25: 1x10ea | M25: 8-9 | N25: =I25 -> 1x10ea | R25: 8-9 | S25: =N25 -> 1x10ea
B26: 4 | C26: 1/2 KN 1-ARM BAND ROW | H26: 8-9 | I26: 1x20 | M26: 8-9 | N26: =I26 -> 1x20 | R26: 8-9 | S26: 1x20
B27: 5 | C27: SEATED 2-ARM OVERHEAD PRESS | H27: 8-9 | I27: 1x20 | M27: 8-9 | N27: =I27 -> 1x20 | R27: 8-9 | S27: 1x20
B28: 6 | C28: SIDE PLANK | H28: 8-9 | I28: 3x10s | M28: 8-9 | N28: =I28 -> 3x10s | R28: 8-9 | S28: =N28 -> 3x10s
B29: 7 | C29: STANDING CABLE "T" | H29: 8-9 | I29: 1x20 | M29: 8-9 | N29: =I29 -> 1x20 | R29: 8-9 | S29: =N29 -> 1x20
B30: 8 | C30: STANDING DB BICEP CURL | H30: 8-9 | I30: 1x20 | M30: 8-9 | N30: =I30 -> 1x20 | R30: 8-9 | S30: =N30 -> 1x20
B31: 9 | C31: STANDING BAND/CABLE TRICEP CURL | H31: 8-9 | I31: 1x20 | M31: 8-9 | N31: =I31 -> 1x20 | R31: 8-9 | S31: =N31 -> 1x20
B32: 10 | C32: BKWD CRAWL | H32: 8-9 | I32: 1x10m | M32: 8-9 | N32: 1x12m | R32: 8-9 | S32: 1x15m
B33: 11 | C33: RACKET SUPINATION/PRONATION | H33: 8-9 | I33: 1x20 | M33: 8-9 | N33: =I33 -> 1x20 | R33: 8-9 | S33: =N33 -> 1x20
B34: 12 | C34: TENNISBALL SQUEZZE GREEN | H34: 8-9 | I34: 1x20 | M34: 8-9 | N34: =I34 -> 1x20 | R34: 8-9 | S34: =N34 -> 1x20
B35: Halteübungen 2
B36: 13 | C36: ISO HOLD PUSH UP PLANK | H36: 8-9 | I36: 1x45s | M36: 8-9 | N36: 1x45s | R36: 8-9 | S36: =N36 -> 1x45s
B37: 14 | C37: ISO HOLD PULL UP PASSIV LOW | H37: 8-9 | I37: 1x45s | M37: =H37 -> 8-9 | N37: =I37 -> 1x45s | R37: =M37 -> 8-9 | S37: =N37 -> 1x45s
B38: 15 | C38: ISO HOLD PRONE BENCH "T" | H38: 8-9 | I38: 1x45s | M38: 8-9 | N38: =I38 -> 1x45s | R38: 8-9 | S38: =N36 -> 1x45s
B39: 16 | C39: ISO HOLD 1/2 KN 1-ARM LANDMINE OVERHEAD PRESS | H39: 8-9 | I39: 1x45ea | M39: 8-9 | N39: =I39 -> 1x45ea | R39: 8-9 | S39: =I39 -> 1x45ea
V40: 1x15s
V41: 1x20s
V42: 1x25s
V43: 1x30s
V44: 1x45s
V45: 1x60s
V46: 3x10s
V47: 1x20
V48: 1x45ea

Sheet UnterkörperC
E2: Körperkonstitution | M2: Current Goals | O2: Logo
C3: Unterkörper
E4: Größe
C5: NAME | E5: Gewicht
C10: Preparatory | E10: General Preparation | I10: Technical Development | N10: Accumulation | Q10: Dynamic | S10: 1x20
B12: TGU - ELBOW TO POST | E12: SIDE CRAWL | I12: 1KB BOTTOM-UP WAITER CARRY | M12: HEARTBEAT SQUAT | O12: HINGE TO CRUSH HANDLE | S12: 1-ARM SUPPORTED 1-LEG ISO HINGE
B14: ANKLE ROCKER 1/2-KN | E14: SPLIT TOE STANCE | I14: ANKLE BOUNDS | M14: 1-LEG B-SKIP | O14: 2-LEG DROP & CATCH & SQUAT JUMP | S14: SQUAT JUMP - DC
B15: Level C | G15: Block 1 | X15: Level
G16: Datum 1 | H16: Woche 1 | J16: Datum 2 | L16: Datum 3 | M16: Woche 2 | O16: Datum 4 | Q16: Datum 5 | R16: Woche 3 | T16: Datum 6 | X16: Level A
B17: Explosiv Block | G17: TEMPO | H17: RPE | I17: SxR | J17: GEWICHT | L17: TEMPO | M17: RPE | N17: SxR | O17: GEWICHT | Q17: TEMPO | R17: RPE | S17: SxR | T17: GEWICHT | X17: Level B
B18: 1 | C18: 2-LEG ROPE SKIPPINGS - 3 CONTACTS | G18: EXPL | I18: 3x100 | J18: BW | L18: EXPL | N18: 3x125 | O18: BW | Q18: EXPL | S18: 3x150 | T18: BW | X18: Level C
B19: 2 | C19: SPLIT STANCE BASKETBALL SIDE TOSS AND CATCH - PARALLEL | G19: EXPL | I19: 3x5 | L19: EXPL | N19: 3x5 | Q19: EXPL | S19: 3x5
B20: 3 | C20: SPLIT STANCE BASKETBALL SIDE TOSS AND CATCH - 90° | G20: EXPL | I20: 3x5 | L20: EXPL | N20: 3x5 | Q20: EXPL | S20: 3x5
B22: Kraft Block (UKK) | G22: GEWICHT | H22: RPE | I22: SxR | J22: GEWICHT | L22: =G22 -> GEWICHT | M22: RPE | N22: SxR | O22: GEWICHT | Q22: =L22 -> GEWICHT | R22: RPE | S22: SxR | T22: GEWICHT
B23: 1 | C23: HEARTBEAT SQUAT | H23: 8-9 | I23: 1x20 | M23: 8-9 | N23: =I23 -> 1x20 | R23: 8-9 | S23: =N23 -> 1x20
B24: 2 | C24: 1-ARM SUPPORTED 1-LEG ISO HINGE | H24: 8-9 | I24: 1x10/ea | M24: 8-9 | N24: =I24 -> 1x10/ea | R24: 8-9 | S24: =N24 -> 1x10/ea
B25: 3 | C25: PUSH UP - SHOULDER TAP | H25: 8-9 | I25: 1x10ea | M25: 8-9 | N25: =I25 -> 1x10ea | R25: 8-9 | S25: =N25 -> 1x10ea
B26: 4 | C26: HINGE TO CRUSH HANDLE (KB SUMO DEADLIFT) | H26: 8-9 | I26: 1x20 | M26: 8-9 | N26: =I26 -> 1x20 | R26: 8-9 | S26: 1x20
B27: 5 | C27: BW STEP FORWARD SPLIT SQUAT TO GROUND WITH STICK | H27: 8-9 | I27: 1x20/ea | M27: 8-9 | N27: =I27 -> 1x20/ea | R27: 8-9 | S27: 1x20
B28: 6 | C28: SIDE PLANK ROTATIONS | H28: 8-9 | I28: 3x10s/ea | M28: 8-9 | N28: =I28 -> 3x10s/ea | R28: 8-9 | S28: =N28 -> 3x10s/ea
B29: 7 | C29: STEP UP MEDIUM STEPPER | H29: 8-9 | I29: 1x20/ea | M29: 8-9 | N29: =I29 -> 1x20/ea | R29: 8-9 | S29: =N29 -> 1x20/ea
B30: 8 | C30: 1-LEG STANCE | H30: 8-9 | I30: 1x30s/ea | M30: 8-9 | N30: =I30 -> 1x30s/ea | R30: 8-9 | S30: =N30 -> 1x30s/ea
B31: 9 | C31: 1/2-KN ANTI-ROTATION PRESS TO OVERHEAD | H31: 8-9 | I31: 3x10s/ea | M31: 8-9 | N31: =I31 -> 3x10s/ea | R31: 8-9 | S31: =N31 -> 3x10s/ea
B32: 10 | C32: HEARBEAT LATERAL SPLIT SQUAT TO BOX | H32: 8-9 | I32: 1x20/ea | M32: 8-9 | N32: 1x12m | R32: 8-9 | S32: 1x15m
B33: 11 | C33: 1-LEG GLUTE BRIDGE | H33: 8-9 | I33: 1x20/ea | M33: 8-9 | N33: =I33 -> 1x20/ea | R33: 8-9 | S33: =N33 -> 1x20/ea
B34: 12 | C34: STANDING MINIBAND HIP EXTERNAL ROTATION | H34: 8-9 | I34: 1x20/ea | M34: 8-9 | N34: =I34 -> 1x20/ea | R34: 8-9 | S34: =N34 -> 1x20/ea
B35: 13 | C35: SIDE MARCH WITH MINIBAND OVER KNEE | H35: 8-9 | I35: 1x15m/ea | M35: 8-9 | N35: =I35 -> 1x15m/ea | R35: 8-9 | S35: =I35 -> 1x15m/ea
B36: 14 | C36: KN COPENHAGEN PLANK BENCH | H36: 8-9 | I36: 3x10s/ea | M36: 8-9 | N36: =I36 -> 3x10s/ea | R36: 8-9 | S36: =N36 -> 3x10s/ea
B37: 15 | C37: SEATED TIBIA BAND RAISE | H37: 8-9 | I37: 1x20/ea | M37: 8-9 | N37: =I37 -> 1x20/ea | R37: 8-9 | S37: =N37 -> 1x20/ea
B38: 16 | C38: LOADED 2-LEG CALF RAISES | H38: 8-9 | I38: 1x20 | M38: 8-9 | N38: =I38 -> 1x20 | R38: 8-9 | S38: =N38 -> 1x20
B39: Halteübungen 1
B40: 17 | C40: ISO HOLD 1-LEG CALF RAISE | H40: 8-9 | I40: 1x60s/ea | M40: 8-9 | N40: =I40 -> 1x60s/ea | R40: 8-9 | S40: =I40 -> 1x60s/ea
B41: 18 | C41: ISO HOLD 1-LEG GLUTE BRIDGE | H41: 8-9 | I41: 1x60s/ea | M41: 8-9 | N41: =I41 -> 1x60s/ea | R41: 8-9 | S41: =I41 -> 1x60s/ea
B42: 19 | C42: ISO HOLD SPLIT SQUAT | H42: 8-9 | I42: 1x60s/ea | M42: 8-9 | N42: =I42 -> 1x60s/ea | R42: 8-9 | S42: =N42 -> 1x60s/ea
V44: 1x15s/ea
V45: 2x12s/ea
V46: 1x25s/ea
V47: 1x30s/ea
V48: 1x45s/ea
V49: 1x60s/ea
...

Sheet OberkörperC
E2: Körperkonstitution | O2: Logo
C3: Oberkörper
E4: Größe
C5: NAME | E5: Gewicht
C10: Preparatory | E10: General Preparation | I10: Technical Development | M10: Accumulation | Q10: Dynamic | S10: =UnterkörperA!#REF! -> #REF!
B12: TGU - ELBOW TO POST | E12: SIDE CRAWL | H12: 1KB BOTTOM-UP WAITER CARRY | L12: HEARTBEAT SQUAT | O12: HINGE TO CRUSH HANDLE | R12: 1-ARM SUPPORTED 1-LEG ISO HINGE
B14: ANKLE ROCKER 1/2-KN | E14: SPLIT TOE STANCE | H14: ANKLE BOUNDS | L14: 1-LEG B-SKIP | O14: 2-LEG DROP & CATCH & SQUAT JUMP | R14: SQUAT JUMP - DC
B15: =UnterkörperC!B15 -> Level C | G15: Block 2
G16: Datum 1 | H16: Woche 1 | J16: Datum 2 | L16: Datum 3 | M16: Woche 2 | O16: Datum 4 | Q16: Datum 5 | R16: Woche 3 | T16: Datum 6
B17: Explosiv Block | G17: TEMPO | H17: RPE | I17: SxR | J17: GEWICHT | L17: TEMPO | M17: RPE | N17: SxR | O17: GEWICHT | Q17: TEMPO | R17: RPE | S17: SxR | T17: GEWICHT
B18: 1 | C18: SQUAT JUMP - TO BOX | G18: EXPL | I18: 3x5 | J18: BW | L18: EXPL | N18: 3x5 | O18: BW | Q18: EXPL | S18: 3x5 | T18: BW
B19: 2 | C19: SPLIT STANCE BASKETBALL OH THROWS WITH PARTNER | G19: EXPL | I19: 3x5 | J19: BB | L19: EXPL | N19: 3x5 | O19: BB | Q19: EXPL | S19: 3x5 | T19: BB
B20: 3 | C20: SPLIT STANCE BASKETBALL 2-ARM CHEST PASSES WITH PARTNER | G20: EXPL | I20: 3x5 | J20: BB | L20: EXPL | N20: 3x5 | O20: BB | Q20: EXPL | S20: 3x5 | T20: BB
B22: Kraft Block (OKK) | G22: GEWICHT | H22: RPE | I22: SxR | J22: GEWICHT | L22: =G22 -> GEWICHT | M22: RPE | N22: SxR | O22: GEWICHT | Q22: =L22 -> GEWICHT | R22: RPE | S22: SxR | T22: GEWICHT
B23: 1 | C23: ARMS ELEVATED PUSH UP LOW | H23: 8-9 | I23: 1x20 | M23: 8-9 | N23: =I23 -> 1x20 | R23: 8-9 | S23: =N23 -> 1x20
B24: 2 | C24: PULL UP HANG PASSIVE LOW | H24: 8-9 | I24: 1x20 | M24: 8-9 | N24: =I24 -> 1x20 | R24: 8-9 | S24: =N24 -> 1x20
B25: 3 | C25: PUSH UP - SHOULDER TAP | H25: 8-9 | I25: 1x10ea | M25: 8-9 | N25: =I25 -> 1x10ea | R25: 8-9 | S25: =N25 -> 1x10ea
B26: 4 | C26: SITTING ON THE FLOOR 2-ARM BAND ROW | H26: 8-9 | I26: 1x20 | M26: 8-9 | N26: =I26 -> 1x20 | R26: 8-9 | S26: 1x20
B27: 5 | C27: SITTING ON THE FLOOR 1 ARM OVERHEAD PRESS | H27: 8-9 | I27: 1x20/ea | M27: 8-9 | N27: =I27 -> 1x20/ea | R27: 8-9 | S27: =I27 -> 1x20/ea
B28: 6 | C28: SIDE PLANK ROTATIONS | H28: 8-9 | I28: 3x10s/ea | M28: 8-9 | N28: =I28 -> 3x10s/ea | R28: 8-9 | S28: =N28 -> 3x10s/ea
B29: 7 | C29: STANDIG CABLE FACE PULL | H29: 8-9 | I29: 1x20 | M29: 8-9 | N29: =I29 -> 1x20 | R29: 8-9 | S29: =N29 -> 1x20
B30: 8 | C30: STANDING BB BICEP CURL | H30: 8-9 | I30: 1x20 | M30: 8-9 | N30: =I30 -> 1x20 | R30: 8-9 | S30: =N30 -> 1x20
B31: 9 | C31: STANDING BAND/CABLE 2-ARM TRICEP CURL | H31: 8-9 | I31: 1x20 | M31: 8-9 | N31: =I31 -> 1x20 | R31: 8-9 | S31: =N31 -> 1x20
B32: 10 | C32: SIDE CRAWL | H32: 8-9 | I32: 1x10m | M32: 8-9 | N32: 1x12m | R32: 8-9 | S32: 1x15m
B33: 11 | C33: LOADED ARM SUPINATION/PRONATION | H33: 8-9 | I33: 1x20/ea | M33: 8-9 | N33: =I33 -> 1x20/ea | R33: 8-9 | S33: =N33 -> 1x20/ea
B34: 12 | C34: FLEXBAR WRING VERTICAL | H34: 8-9 | I34: 1x20/ea | M34: 8-9 | N34: =I34 -> 1x20/ea | R34: 8-9 | S34: =N34 -> 1x20/ea
B35: Halteübungen 2
B36: 13 | C36: ISO HOLD PUSH UP PLANK | H36: 8-9 | I36: 1x60s | M36: 8-9 | N36: 1x60s | R36: 8-9 | S36: =N36 -> 1x60s
B37: 14 | C37: ISO HOLD PULL UP PASSIV LOW | H37: 8-9 | I37: 1x60s | M37: =H37 -> 8-9 | N37: =I37 -> 1x60s | R37: =M37 -> 8-9 | S37: =N37 -> 1x60s
B38: 15 | C38: ISO HOLD PRONE BENCH "T" | H38: 8-9 | I38: 1x60s | M38: 8-9 | N38: =I38 -> 1x60s | R38: 8-9 | S38: =N36 -> 1x60s
B39: 16 | C39: ISO HOLD 1/2 KN 1-ARM LANDMINE OVERHEAD PRESS | H39: 8-9 | I39: 1x60s/ea | M39: 8-9 | N39: =I39 -> 1x60s/ea | R39: 8-9 | S39: =I39 -> 1x60s/ea
V40: 1x15s
V41: 1x20s
V42: 1x25s
V43: 1x30s
V44: 1x45s
V45: 1x60s
V46: 3x10s
V47: 1x20
V48: 1x45ea

Sheet UnterkörperD
E2: Körperkonstitution | O2: Logo
C3: Unterkörper
E4: Größe
C5: NAME | E5: Gewicht
C10: Preparatory | E10: General Preparation | I10: Technical Development | N10: Accumulation | Q10: Dynamic | S10: 1x20
B12: TGU ROLL TO 1-ARM PRESS SHOE BALANCE | E12: FOOT ELBOW CRAWL | I12: 2-ARM RACK CARRY | M12: KB GOBLET SQUAT | O12: HINGE TO SNIFF AIR | S12: STICK SUP 1-LEG HINGE
B14: ANKLE ROCKER SHUFFLE | E14: SPLIT SQUAT TOE STANCE | I14: LATERAL ANKLE MARCH | M14: B-SKIP | O14: 1-LEG DROP & CATCH & SIDE BOUND | S14: REACTIVE SQUAT JUMP
B15: Level D | G15: Block 1 | X15: Level
G16: Datum 1 | H16: Woche 1 | J16: Datum 2 | L16: Datum 3 | M16: Woche 2 | O16: Datum 4 | Q16: Datum 5 | R16: Woche 3 | T16: Datum 6 | X16: Level A
B17: Explosiv Block | G17: TEMPO | H17: RPE | I17: SxR | J17: GEWICHT | L17: TEMPO | M17: RPE | N17: SxR | O17: GEWICHT | Q17: TEMPO | R17: RPE | S17: SxR | T17: GEWICHT | X17: Level B
B18: 1 | C18: DOUBLE JUMP 2-LEG ROPE SKIPPING | G18: EXPL | I18: 3x3x10 | J18: BW | L18: EXPL | N18: 3x2x15 | O18: BW | Q18: EXPL | S18: 3x2x20 | T18: BW | X18: Level C
B19: 2 | C19: SPLIT STANCE BASKETBALL SIDE TOSS - PARALLEL | G19: EXPL | I19: 3x5 | L19: EXPL | N19: 3x5 | Q19: EXPL | S19: 3x5 | X19: Level D
B20: 3 | C20: SPLIT STANCE BASKETBALL SIDE TOSS - 90° | G20: EXPL | I20: 3x5 | L20: EXPL | N20: 3x5 | Q20: EXPL | S20: 3x5
B22: Kraft Block (UKK) | G22: GEWICHT | H22: RPE | I22: SxR | J22: GEWICHT | L22: =G22 -> GEWICHT | M22: RPE | N22: SxR | O22: GEWICHT | Q22: =L22 -> GEWICHT | R22: RPE | S22: SxR | T22: GEWICHT
B23: 1 | C23: KB GOBLET SQUAT | H23: 8-9 | I23: 1x20 | M23: 8-9 | N23: =I23 -> 1x20 | R23: 8-9 | S23: =N23 -> 1x20
B24: 2 | C24: STICK SUPPOERTED 1-LEG HINGE | H24: 8-9 | I24: 1x20/ea | M24: 8-9 | N24: =I24 -> 1x20/ea | R24: 8-9 | S24: =N24 -> 1x20/ea
B25: 3 | C25: PLANK - SWITCH IN FRONT | H25: 8-9 | I25: 1x10ea | M25: 8-9 | N25: =I25 -> 1x10ea | R25: 8-9 | S25: =N25 -> 1x10ea
B26: 4 | C26: HINGE TO SNIFF AIR (KB SUMO DEADLIFT) | H26: 8-9 | I26: 1x20 | M26: 8-9 | N26: =I26 -> 1x20 | R26: 8-9 | S26: 1x20
B27: 5 | C27: BW BOTTON-UP SPLIT SQUAT | H27: 8-9 | I27: 1x20/ea | M27: 8-9 | N27: =I27 -> 1x20/ea | R27: 8-9 | S27: 1x20
B28: 6 | C28: FT ELEVATED SIDE PLANK | H28: 8-9 | I28: 3x10s/ea | M28: 8-9 | N28: =I28 -> 3x10s/ea | R28: 8-9 | S28: =N28 -> 3x10s/ea
B29: 7 | C29: STEP UP HIGH STEPPER | H29: 8-9 | I29: 1x20/ea | M29: 8-9 | N29: =I29 -> 1x20/ea | R29: 8-9 | S29: =N29 -> 1x20/ea
B30: 8 | C30: 1-LEG STANCE CLOSED EYES | H30: 8-9 | I30: 1x30s/ea | M30: 8-9 | N30: =I30 -> 1x30s/ea | R30: 8-9 | S30: =N30 -> 1x30s/ea
B31: 9 | C31: TK ANTI-ROTATION HOLD | H31: 8-9 | I31: 2x12/ea | M31: 8-9 | N31: =I31 -> 2x12/ea | R31: 8-9 | S31: =N31 -> 2x12/ea
B32: 10 | C32: HEARBEAT LATERAL SPLIT SQUAT | H32: 8-9 | I32: 1x15/ea | M32: 8-9 | N32: =I32 -> 1x15/ea | R32: 8-9 | S32: =I32 -> 1x15/ea
B33: 11 | C33: 2-LEG MARCHING FORWARD GLUTE BRIDGE | H33: 8-9 | I33: 1x20 | M33: 8-9 | N33: =I33 -> 1x20 | R33: 8-9 | S33: =N33 -> 1x20
B34: 12 | C34: STANDING PEZZIBALL EXTERNAL ROTATION | H34: 8-9 | I34: 3x10s/ea | M34: 8-9 | N34: =I34 -> 3x10s/ea | R34: 8-9 | S34: =N34 -> 3x10s/ea
B35: 13 | C35: SIDE MARCH WITH MINIBAND OVER ANKLES | H35: 8-9 | I35: 1x15m/ea | M35: 8-9 | N35: =I35 -> 1x15m/ea | R35: 8-9 | S35: =I35 -> 1x15m/ea
B36: 14 | C36: FOOT COPENHAGENPLANK BENCH | H36: 8-9 | I36: 3x10s/ea | M36: 8-9 | N36: =I36 -> 3x10s/ea | R36: 8-9 | S36: =N36 -> 3x10s/ea
B37: 15 | C37: SEATED TIBIA BAND RAISE | H37: 8-9 | I37: 1x20/ea | M37: 8-9 | N37: =I37 -> 1x20/ea | R37: 8-9 | S37: =N37 -> 1x20/ea
B38: 16 | C38: LOADED 2-LEG CALF RAISES | H38: 8-9 | I38: 1x20 | M38: 8-9 | N38: =I38 -> 1x20 | R38: 8-9 | S38: =N38 -> 1x20
B39: Halteübungen 1
B40: 17 | C40: ISO HOLD 1-LEG CALF RAISE | H40: 8-9 | I40: 1x60s/ea | M40: 8-9 | N40: =I40 -> 1x60s/ea | R40: 8-9 | S40: =I40 -> 1x60s/ea
B41: 18 | C41: ISO HOLD 1-LEG GLUTE BRIDGE | H41: 8-9 | I41: 1x60s/ea | M41: 8-9 | N41: =I41 -> 1x60s/ea | R41: 8-9 | S41: =I41 -> 1x60s/ea
B42: 19 | C42: ISO HOLD SPLIT SQUAT | H42: 8-9 | I42: 1x60s/ea | M42: 8-9 | N42: =I42 -> 1x60s/ea | R42: 8-9 | S42: =N42 -> 1x60s/ea
V44: 1x15s/ea
V45: 2x12s/ea
V46: 1x25s/ea
V47: 1x30s/ea
V48: 1x45s/ea
V49: 1x60s/ea
...

Sheet OberkörperD
E2: Körperkonstitution | O2: Logo
C3: Oberkörper
E4: Größe
C5: NAME | E5: Gewicht
C10: Preparatory | E10: General Preparation | I10: Technical Development | M10: Accumulation | Q10: Dynamic | S10: =UnterkörperA!#REF! -> #REF!
B12: TGU ROLL TO 1-ARM PRESS SHOE BALANCE | E12: FOOT ELBOW CRAWL | H12: 2-ARM RACK CARRY | L12: KB GOBLET SQUAT | O12: HINGE TO SNIFF AIR | R12: STICK SUP 1-LEG HINGE
B14: ANKLE ROCKER SHUFFLE | E14: SPLIT SQUAT TOE STANCE | H14: LATERAL ANKLE MARCH | L14: B-SKIP | O14: 1-LEG DROP & CATCH & SIDE BOUND | R14: REACTIVE SQUAT JUMP
B15: =UnterkörperD!B15 -> Level D | G15: Block 2
G16: Datum 1 | H16: Woche 1 | J16: Datum 2 | L16: Datum 3 | M16: Woche 2 | O16: Datum 4 | Q16: Datum 5 | R16: Woche 3 | T16: Datum 6
B17: Explosiv Block | G17: TEMPO | H17: RPE | I17: SxR | J17: GEWICHT | L17: TEMPO | M17: RPE | N17: SxR | O17: GEWICHT | Q17: TEMPO | R17: RPE | S17: SxR | T17: GEWICHT
B18: 1 | C18: CM JUMP - TO BOX | G18: EXPL | I18: 3x5 | J18: BW | L18: EXPL | N18: 3x5 | O18: BW | Q18: EXPL | S18: 3x5 | T18: BW
B19: 2 | C19: SPLIT STANCE MB OH THROWS INTO WALL | G19: EXPL | I19: 3x5 | J19: BB | L19: EXPL | N19: 3x5 | O19: BB | Q19: EXPL | S19: 3x5 | T19: BB
B20: 3 | C20: SPLIT STANCE BASKETBALL 2-ARM CHEST PASSES INTO WALL | G20: EXPL | I20: 3x5 | J20: BB | L20: EXPL | N20: 3x5 | O20: BB | Q20: EXPL | S20: 3x5 | T20: BB
B22: Kraft Block (OKK) | G22: GEWICHT | H22: RPE | I22: SxR | J22: GEWICHT | L22: =G22 -> GEWICHT | M22: RPE | N22: SxR | O22: GEWICHT | Q22: =L22 -> GEWICHT | R22: RPE | S22: SxR | T22: GEWICHT
B23: 1 | C23: PUSH UP ON KNEE | H23: 8-9 | I23: 1x20 | M23: 8-9 | N23: =I23 -> 1x20 | R23: 8-9 | S23: =N23 -> 1x20
B24: 2 | C24: PULL UP HANG AKTIVE LOW | H24: 8-9 | I24: 1x20 | M24: 8-9 | N24: =I24 -> 1x20 | R24: 8-9 | S24: =N24 -> 1x20
B25: 3 | C25: PLANK - SWITCH IN FRONT | H25: 8-9 | I25: 1x10ea | M25: 8-9 | N25: =I25 -> 1x10ea | R25: 8-9 | S25: =N25 -> 1x10ea
B26: 4 | C26: STANDING 2-ARM BAND ROW | H26: 8-9 | I26: 1x20 | M26: 8-9 | N26: =I26 -> 1x20 | R26: 8-9 | S26: 1x20
B27: 5 | C27: SITTING ON THE FLOOR 2 ARM OVERHEAD PRESS | H27: 8-9 | I27: 1x20/ea | M27: 8-9 | N27: =I27 -> 1x20/ea | R27: 8-9 | S27: =I27 -> 1x20/ea
B28: 6 | C28: FT ELEVATED SIDE PLANK | H28: 8-9 | I28: 3x10s/ea | M28: 8-9 | N28: =I28 -> 3x10s/ea | R28: 8-9 | S28: =N28 -> 3x10s/ea
B29: 7 | C29: PRONE BENCH ROW TO "W" | H29: 8-9 | I29: 1x20 | M29: 8-9 | N29: =I29 -> 1x20 | R29: 8-9 | S29: =N29 -> 1x20
B30: 8 | C30: STANDING BB BICEP CURL | H30: 8-9 | I30: 1x20 | M30: 8-9 | N30: =I30 -> 1x20 | R30: 8-9 | S30: =N30 -> 1x20
B31: 9 | C31: SUPPORTED DIPS | H31: 8-9 | I31: 1x20 | M31: 8-9 | N31: =I31 -> 1x20 | R31: 8-9 | S31: =N31 -> 1x20
B32: 10 | C32: FOOT ELBOW CRAWL | H32: 8-9 | I32: 1x10m | M32: 8-9 | N32: 1x12m | R32: 8-9 | S32: 1x15m
B33: 11 | C33: LOADED ARM SUPINATION/PRONATION | H33: 8-9 | I33: 1x20/ea | M33: 8-9 | N33: =I33 -> 1x20/ea | R33: 8-9 | S33: =N33 -> 1x20/ea
B34: 12 | C34: FLEXBAR WRING HORIZONAL | H34: 8-9 | I34: 1x20/ea | M34: 8-9 | N34: =I34 -> 1x20/ea | R34: 8-9 | S34: =N34 -> 1x20/ea
B35: Halteübungen 2
B36: 13 | C36: ISO HOLD FT ELEVATED PUSH UP PLANK | H36: 8-9 | I36: 1x30s | M36: 8-9 | N36: 1x30s | R36: 8-9 | S36: =N36 -> 1x30s
B37: 14 | C37: ISO HOLD PULL UP ACTIVE LOW | H37: 8-9 | I37: 1x30s | M37: =H37 -> 8-9 | N37: =I37 -> 1x30s | R37: =M37 -> 8-9 | S37: =N37 -> 1x30s
B38: 15 | C38: ISO HOLD PRONE BENCH "V" | H38: 8-9 | I38: 1x30s | M38: 8-9 | N38: =I38 -> 1x30s | R38: 8-9 | S38: =N36 -> 1x30s
B39: 16 | C39: ISO HOLD 1/2 KN 1-ARM LANDMINE OVERHEAD PRESS | H39: 8-9 | I39: 1x30s/ea | M39: 8-9 | N39: =I39 -> 1x30s/ea | R39: 8-9 | S39: =I39 -> 1x30s/ea
V40: 1x15s
V41: 1x20s
V42: 1x25s
V43: 1x30s
V44: 1x45s
V45: 1x60s
V48: 3x10s
V49: 1x20
V50: 1x45ea

Sheet UnterkörperE
E2: Körperkonstitution | O2: Logo
C3: Unterkörper
E4: Größe
C5: NAME | E5: Gewicht
C10: Preparatory | E10: General Preparation | I10: Technical Development | N10: Accumulation | Q10: Dynamic | S10: 1x20
B12: 1-ARM PRESS TO ELBOW SHOE BALANCE | E12: PUSH UP CRAWL | I12: 2KB BOTTOM-UP WAITER CARRY | M12: BW RACK SQUAT | O12: STICK DEADLIFT | S12: 1-LEG HINGE WITH ARMS STRETCHED
B14: ANKLE ROCKER SPLIT SQUAT | E14: SQUAT TOE STANCE | I14: LATERAL ANKLE SKIP | M14: 1-LEG C-SKIP | O14: SPLIT SQUAT DROP & CATCH | S14: REAKTIV CMJ
B15: Level E | G15: Block 1 | X15: Level
G16: Datum 1 | H16: Woche 1 | J16: Datum 2 | L16: Datum 3 | M16: Woche 2 | O16: Datum 4 | Q16: Datum 5 | R16: Woche 3 | T16: Datum 6 | X16: Level A
B17: Explosiv Block | G17: TEMPO | H17: RPE | I17: SxR | J17: GEWICHT | L17: TEMPO | M17: RPE | N17: SxR | O17: GEWICHT | Q17: TEMPO | R17: RPE | S17: SxR | T17: GEWICHT | X17: Level B
B18: 1 | C18: ANKLE JUMPS - DOUBLE CONTACT | G18: EXPL | I18: 3x3x10 | J18: BW | L18: EXPL | N18: 3x2x15 | O18: BW | Q18: EXPL | S18: 3x2x20 | T18: BW | X18: Level C
B19: 2 | C19: 1-LEG BASKETBALL SIDE TOSS AND CATCH - PARALLEL | G19: EXPL | I19: 3x5 | L19: EXPL | N19: 3x5 | Q19: EXPL | S19: 3x5 | X19: Level D
B20: 3 | C20: 1-LEG BASKETBALL SIDE TOSS AND CATCH - 90° | G20: EXPL | I20: 3x5 | L20: EXPL | N20: 3x5 | Q20: EXPL | S20: 3x5 | X20: Level E
B22: Kraft Block (UKK) | G22: GEWICHT | H22: RPE | I22: SxR | J22: GEWICHT | L22: =G22 -> GEWICHT | M22: RPE | N22: SxR | O22: GEWICHT | Q22: =L22 -> GEWICHT | R22: RPE | S22: SxR | T22: GEWICHT
B23: 1 | C23: BW RACK SQUAT | H23: 8-9 | I23: 1x20 | M23: 8-9 | N23: =I23 -> 1x20 | R23: 8-9 | S23: =N23 -> 1x20
B24: 2 | C24: 1-LEG HINGE WITH ARMS STRETCHED | H24: 8-9 | I24: 1x10/ea | M24: 8-9 | N24: =I24 -> 1x10/ea | R24: 8-9 | S24: =N24 -> 1x10/ea
B25: 3 | C25: PUSH UP PLANK TENNISBALL CATCH | H25: 8-9 | I25: 1x10ea | M25: 8-9 | N25: =I25 -> 1x10ea | R25: 8-9 | S25: =N25 -> 1x10ea
B26: 4 | C26: STICK DEADLIFT | H26: 8-9 | I26: 1x20 | M26: 8-9 | N26: =I26 -> 1x20 | R26: 8-9 | S26: 1x20
B27: 5 | C27: KB GOBLET SPLIT SQUAT | H27: 8-9 | I27: 1x20/ea | M27: 8-9 | N27: =I27 -> 1x20/ea | R27: 8-9 | S27: 1x20
B28: 6 | C28: SIDE PLANK WITH LEG ABDUCTION | H28: 8-9 | I28: 3x10s | M28: 8-9 | N28: =I28 -> 3x10s | R28: 8-9 | S28: =N28 -> 3x10s
B29: 7 | C29: CROSS STEP UP MEDIUM STEPPER | H29: 8-9 | I29: 1x20/ea | M29: 8-9 | N29: =I29 -> 1x20/ea | R29: 8-9 | S29: =N29 -> 1x20/ea
B30: 8 | C30: 1-LEG STANCE HEAD ROTATION - EYES FOCUS | H30: 8-9 | I30: 1x30s/ea | M30: 8-9 | N30: =I30 -> 1x30s/ea | R30: 8-9 | S30: =N30 -> 1x30s/ea
B31: 9 | C31: TK ANTI-ROTATION PRESS | H31: 8-9 | I31: 2x12/ea | M31: 8-9 | N31: =I31 -> 2x12/ea | R31: 8-9 | S31: =N31 -> 2x12/ea
B32: 10 | C32: GOBLET LATERAL SPLIT SQUAT TO BOX | H32: 8-9 | I32: 1x12/ea | M32: 8-9 | N32: =I32 -> 1x12/ea | R32: 8-9 | S32: =I32 -> 1x12/ea
B33: 11 | C33: 2-LEG MARCHING FORWARD GLUTE BRIDGE WITH BLACKROLL | H33: 8-9 | I33: 1x12 | M33: 8-9 | N33: =I33 -> 1x12 | R33: 8-9 | S33: =N33 -> 1x12
B34: 12 | C34: 1-LEG STANDING MINIBAND HIP EXTERNAL ROTATION | H34: 8-9 | I34: 1x20/ea | M34: 8-9 | N34: =I34 -> 1x20/ea | R34: 8-9 | S34: =N34 -> 1x20/ea
B35: 13 | C35: SIDE MARCH WITH MINIBAND OVER FOOT | H35: 8-9 | I35: 1x15m/ea | M35: 8-9 | N35: =I35 -> 1x15m/ea | R35: 8-9 | S35: =I35 -> 1x15m/ea
B36: 14 | C36: FOOT COPENHAGEN PLANK BLACKROLL | H36: 8-9 | I36: 3x10s/ea | M36: 8-9 | N36: =I36 -> 3x10s/ea | R36: 8-9 | S36: =N36 -> 3x10s/ea
B37: 15 | C37: SEATED TIBIA BAND RAISE | H37: 8-9 | I37: 1x20/ea | M37: 8-9 | N37: =I37 -> 1x20/ea | R37: 8-9 | S37: =N37 -> 1x20/ea
B38: 16 | C38: LOADED 1-LEG CALF RAISES | H38: 8-9 | I38: 1x20/ea | M38: 8-9 | N38: =I38 -> 1x20/ea | R38: 8-9 | S38: =N38 -> 1x20/ea
B39: Halteübungen 1
B40: 17 | C40: ISO HOLD 1-LEG CALF RAISE | H40: 8-9 | I40: 1x75s/ea | M40: 8-9 | N40: =I40 -> 1x75s/ea | R40: 8-9 | S40: =I40 -> 1x75s/ea
B41: 18 | C41: ISO HOLD 1-LEG GLUTE BRIDGE | H41: 8-9 | I41: 1x75s/ea | M41: 8-9 | N41: =I41 -> 1x75s/ea | R41: 8-9 | S41: =I41 -> 1x75s/ea
B42: 19 | C42: ISO HOLD SPLIT SQUAT | H42: 8-9 | I42: 1x75s/ea | M42: 8-9 | N42: =I42 -> 1x75s/ea | R42: 8-9 | S42: =N42 -> 1x75s/ea
V44: 1x15s/ea
V45: 2x12s/ea
V46: 1x25s/ea
V47: 1x30s/ea
V48: 1x45s/ea
V49: 1x60s/ea
...

Sheet OberkörperE
E2: Körperkonstitution | O2: Logo
C3: Oberkörper
E4: Größe
C5: NAME | E5: Gewicht
C10: Preparatory | E10: General Preparation | I10: Technical Development | M10: Accumulation | Q10: Dynamic | S10: =UnterkörperA!#REF! -> #REF!
B12: 1-ARM PRESS TO ELBOW SHOE BALANCE | E12: PUSH UP CRAWL | H12: 2KB BOTTOM-UP WAITER CARRY | L12: BW RACK SQUAT | O12: STICK DEADLIFT | R12: 1-LEG HINGE WITH ARMS STRETCHED
B14: ANKLE ROCKER SPLIT SQUAT | E14: SQUAT TOE STANCE | H14: LATERAL ANKLE SKIP | L14: 1-LEG C-SKIP | O14: SPLIT SQUAT DROP & CATCH | R14: REAKTIV CMJ
B15: =UnterkörperE!B15 -> Level E | G15: Block 2
G16: Datum 1 | H16: Woche 1 | J16: Datum 2 | L16: Datum 3 | M16: Woche 2 | O16: Datum 4 | Q16: Datum 5 | R16: Woche 3 | T16: Datum 6
B17: Explosiv Block | G17: TEMPO | H17: RPE | I17: SxR | J17: GEWICHT | L17: TEMPO | M17: RPE | N17: SxR | O17: GEWICHT | Q17: TEMPO | R17: RPE | S17: SxR | T17: GEWICHT
B18: 1 | C18: REACTIVE SQUAT JUMP | G18: EXPL | I18: 3x5 | J18: BW | L18: EXPL | N18: 3x5 | O18: BW | Q18: EXPL | S18: 3x5 | T18: BW
B19: 2 | C19: 1-LEG BASKETBALL OH THROW WITH PARTNER | G19: EXPL | I19: 3x5 | J19: BB | L19: EXPL | N19: 3x5 | O19: BB | Q19: EXPL | S19: 3x5 | T19: BB
B20: 3 | C20: 1-LEG BASKETBALL CHEST PASS WITH PARTNER | G20: EXPL | I20: 3x5 | J20: BB | L20: EXPL | N20: 3x5 | O20: BB | Q20: EXPL | S20: 3x5 | T20: BB
B22: Kraft Block (OKK) | G22: GEWICHT | H22: RPE | I22: SxR | J22: GEWICHT | L22: =G22 -> GEWICHT | M22: RPE | N22: SxR | O22: GEWICHT | Q22: =L22 -> GEWICHT | R22: RPE | S22: SxR | T22: GEWICHT
B23: 1 | C23: ECC PUSH UP ON KNEE UP | H23: 8-9 | I23: 1x10 | M23: 8-9 | N23: =I23 -> 1x10 | R23: 8-9 | S23: =N23 -> 1x10
B24: 2 | C24: PULL UP ECC | H24: 8-9 | I24: 1x8 | M24: 8-9 | N24: =I24 -> 1x8 | R24: 8-9 | S24: =N24 -> 1x8
B25: 3 | C25: STRAIGHT LEG GET UP | H25: 8-9 | I25: 1x10ea | M25: 8-9 | N25: =I25 -> 1x10ea | R25: 8-9 | S25: =N25 -> 1x10ea
B26: 4 | C26: STANDING 1-ARM BAND ROW | H26: 8-9 | I26: 1x20 | M26: 8-9 | N26: =I26 -> 1x20 | R26: 8-9 | S26: 1x20
B27: 5 | C27: 1/2 KN 1-ARM OVERHEAD PRESS | H27: 8-9 | I27: 1x20/ea | M27: 8-9 | N27: =I27 -> 1x20/ea | R27: 8-9 | S27: =I27 -> 1x20/ea
B28: 6 | C28: SIDE PLANK WITH LEG ABDUCTION | H28: 8-9 | I28: 3x10s/ea | M28: 8-9 | N28: =I28 -> 3x10s/ea | R28: 8-9 | S28: =N28 -> 3x10s/ea
B29: 7 | C29: PRONE BENCH DB "V" RAISE | H29: 8-9 | I29: 1x20 | M29: 8-9 | N29: =I29 -> 1x20 | R29: 8-9 | S29: =N29 -> 1x20
B30: 8 | C30: STANDING BB BICEP CURL | H30: 8-9 | I30: 1x20 | M30: 8-9 | N30: =I30 -> 1x20 | R30: 8-9 | S30: =N30 -> 1x20
B31: 9 | C31: SUPPORTED DIPS | H31: 8-9 | I31: 1x20 | M31: 8-9 | N31: =I31 -> 1x20 | R31: 8-9 | S31: =N31 -> 1x20
B32: 10 | C32: PUSH UP CRAWL | H32: 8-9 | I32: 1x10m | M32: 8-9 | N32: 1x12m | R32: 8-9 | S32: 1x15m
B33: 11 | C33: LOADED ARM SUPINATION/PRONATION | H33: 8-9 | I33: 1x20/ea | M33: 8-9 | N33: =I33 -> 1x20/ea | R33: 8-9 | S33: =N33 -> 1x20/ea
B34: 12 | C34: FLEXBAR BREAKING DOWN | H34: 8-9 | I34: 1x20/ea | M34: 8-9 | N34: =I34 -> 1x20/ea | R34: 8-9 | S34: =N34 -> 1x20/ea
B35: Halteübungen 2
B36: 13 | C36: ISO HOLD FT ELEVATED PUSH UP PLANK | H36: 8-9 | I36: 1x45s | M36: 8-9 | N36: 1x45s | R36: 8-9 | S36: =N36 -> 1x45s
B37: 14 | C37: ISO HOLD PULL UP ACTIVE LOW | H37: 8-9 | I37: 1x45s | M37: =H37 -> 8-9 | N37: =I37 -> 1x45s | R37: =M37 -> 8-9 | S37: =N37 -> 1x45s
B38: 15 | C38: ISO HOLD PRONE BENCH "V" | H38: 8-9 | I38: 1x45s | M38: 8-9 | N38: =I38 -> 1x45s | R38: 8-9 | S38: =N36 -> 1x45s
B39: 16 | C39: ISO HOLD 1/2 KN 1-ARM LANDMINE OVERHEAD PRESS | H39: 8-9 | I39: 1x45s/ea | M39: 8-9 | N39: =I39 -> 1x45s/ea | R39: 8-9 | S39: =I39 -> 1x45s/ea
V40: 1x15s
V41: 1x20s
V42: 1x25s
V43: 1x30s
V44: 1x45s
V45: 1x60s
V46: 1x8
V47: 1x10
V48: 3x10s
...

Sheet UnterkörperF
E2: Körperkonstitution | O2: Logo
C3: Unterkörper
E4: Größe
C5: NAME | E5: Gewicht
C10: Preparatory | E10: General Preparation | I10: Technical Development | N10: Accumulation | Q10: Dynamic | S10: 1x20
B12: TGU - ELBOW TO POST SHOE BALANCE | E12: LATERAL PUSH UP CRAWL | I12: 1KB OVERHEAD CARRY | M12: BW 1-ARM OVERHEAD SQUAT | O12: 1 KB DEADLIFT | S12: 1-LEG HINGE WITH MED/PEZZIBALL
B14: ANKLE ROCKER MOONWALK | E14: 1-LEG TOE STANCE | I14: LATERAL BOUND | M14: C-SKIP | O14: SPLIT SQUAT DROP & CATCH & JUMP | S14: SQUAT JUMPS
B15: Level F | G15: Block 1 | X15: Level
G16: Datum 1 | H16: Woche 1 | J16: Datum 2 | L16: Datum 3 | M16: Woche 2 | O16: Datum 4 | Q16: Datum 5 | R16: Woche 3 | T16: Datum 6 | X16: Level A
B17: Explosiv Block | G17: TEMPO | H17: RPE | I17: SxR | J17: GEWICHT | L17: TEMPO | M17: RPE | N17: SxR | O17: GEWICHT | Q17: TEMPO | R17: RPE | S17: SxR | T17: GEWICHT | X17: Level B
B18: 1 | C18: ANKLE JUMPS | G18: EXPL | I18: 3x3x10 | J18: BW | L18: EXPL | N18: 3x2x15 | O18: BW | Q18: EXPL | S18: 3x2x20 | T18: BW | X18: Level C
B19: 2 | C19: 1-LEG BASKETBALL SIDE TOSS - PARALLEL | G19: EXPL | I19: 3x5 | L19: EXPL | N19: 3x5 | Q19: EXPL | S19: 3x5 | X19: Level D
B20: 3 | C20: 1-LEG BASKETBALL SIDE TOSS - 90° | G20: EXPL | I20: 3x5 | L20: EXPL | N20: 3x5 | Q20: EXPL | S20: 3x5 | X20: Level E
X21: Level F
B22: Kraft Block (UKK) | G22: GEWICHT | H22: RPE | I22: SxR | J22: GEWICHT | L22: =G22 -> GEWICHT | M22: RPE | N22: SxR | O22: GEWICHT | Q22: =L22 -> GEWICHT | R22: RPE | S22: SxR | T22: GEWICHT
B23: 1 | C23: BW 1-ARM OVERHEAD SQUAT | H23: 8-9 | I23: 1x10/ea | M23: 8-9 | N23: =I23 -> 1x10/ea | R23: 8-9 | S23: =N23 -> 1x10/ea
B24: 2 | C24: 1-LEG HINGE WITH MED/PEZZIBALL | H24: 8-9 | I24: 1x20/ea | M24: 8-9 | N24: =I24 -> 1x20/ea | R24: 8-9 | S24: =N24 -> 1x20/ea
B25: 3 | C25: PLANK - SWITCH ON BACK | H25: 8-9 | I25: 1x10/ea | M25: 8-9 | N25: =I25 -> 1x10/ea | R25: 8-9 | S25: =N25 -> 1x10/ea
B26: 4 | C26: 1 KB DEADLIFT | H26: 8-9 | I26: 1x20/ea | M26: 8-9 | N26: =I26 -> 1x20/ea | R26: 8-9 | S26: 1x20
B27: 5 | C27: BW BULGARIAN SPLIT SQUAT | H27: 8-9 | I27: 1x20/ea | M27: 8-9 | N27: =I27 -> 1x20/ea | R27: 8-9 | S27: 1x20
B28: 6 | C28: FT ELEVATED SIDE PLANK - BLACKROLL | H28: 8-9 | I28: 3x10s | M28: 8-9 | N28: =I28 -> 3x10s | R28: 8-9 | S28: =N28 -> 3x10s
B29: 7 | C29: CROSS STEP UP HIGH STEPPER | H29: 8-9 | I29: 1x20/ea | M29: 8-9 | N29: =I29 -> 1x20/ea | R29: 8-9 | S29: =N29 -> 1x20/ea
B30: 8 | C30: 1-LEG STANCE HEAD UP AND DOWN - EYES FOCUS | H30: 8-9 | I30: 1x30s/ea | M30: 8-9 | N30: =I30 -> 1x30s/ea | R30: 8-9 | S30: =N30 -> 1x30s/ea
B31: 9 | C31: TK ANTI-ROTATION PRESS TO OVERHEAD | H31: 8-9 | I31: 2x12/ea | M31: 8-9 | N31: =I31 -> 2x12/ea | R31: 8-9 | S31: =N31 -> 2x12/ea
B32: 10 | C32: GOBLET LATERAL SPLIT SQUAT | H32: 8-9 | I32: 1x10/ea | M32: 8-9 | N32: 1x12m | R32: 8-9 | S32: 1x15m
B33: 11 | C33: 2-LEG CURL WITH PEZZIBALL | H33: 8-9 | I33: 1x20 | M33: 8-9 | N33: =I33 -> 1x20 | R33: 8-9 | S33: =N33 -> 1x20
B34: 12 | C34: 1-LEG STANDING MINIBAND HIP EXTERNAL ROTATION | H34: 8-9 | I34: 1x20/ea | M34: 8-9 | N34: =I34 -> 1x20/ea | R34: 8-9 | S34: =N34 -> 1x20/ea
B35: 13 | C35: SIDE MARCH WITH MINIBAND OVER KNEE HEAVY BAND | H35: 8-9 | I35: 1x15m/ea | M35: 8-9 | N35: =I35 -> 1x15m/ea | R35: 8-9 | S35: =I35 -> 1x15m/ea
B36: 14 | C36: FOOT COPENHAGEN PLANK TRX | H36: 8-9 | I36: 3x10s/ea | M36: 8-9 | N36: =I36 -> 3x10s/ea | R36: 8-9 | S36: =N36 -> 3x10s/ea
B37: 15 | C37: SEATED TIBIA BAND RAISE | H37: 8-9 | I37: 1x20/ea | M37: 8-9 | N37: =I37 -> 1x20/ea | R37: 8-9 | S37: =N37 -> 1x20/ea
B38: 16 | C38: LOADED 1-LEG CALF RAISES | H38: 8-9 | I38: 1x20/ea | M38: 8-9 | N38: =I38 -> 1x20/ea | R38: 8-9 | S38: =N38 -> 1x20/ea
B39: Halteübungen 1
B40: 17 | C40: ISO HOLD 1-LEG CALF RAISE | H40: 8-9 | I40: 1x90s/ea | M40: 8-9 | N40: =I40 -> 1x90s/ea | R40: 8-9 | S40: =I40 -> 1x90s/ea
B41: 18 | C41: ISO HOLD 1-LEG GLUTE BRIDGE | H41: 8-9 | I41: 1x90s/ea | M41: 8-9 | N41: =I41 -> 1x90s/ea | R41: 8-9 | S41: =I41 -> 1x90s/ea
B42: 19 | C42: ISO HOLD SPLIT SQUAT | H42: 8-9 | I42: 1x90s/ea | M42: 8-9 | N42: =I42 -> 1x90s/ea | R42: 8-9 | S42: =N42 -> 1x90s/ea
V44: 1x15s/ea
V45: 2x12s/ea
V46: 1x25s/ea
V47: 1x30s/ea
V48: 1x45s/ea
...

Sheet OberkörperF
E2: Körperkonstitution | O2: Logo
C3: Oberkörper
E4: Größe
C5: NAME | E5: Gewicht
C10: Preparatory | E10: General Preparation | I10: Technical Development | M10: Accumulation | Q10: Dynamic | S10: =UnterkörperA!#REF! -> #REF!
B12: TGU - ELBOW TO POST SHOE BALANCE | E12: LATERAL PUSH UP CRAWL | H12: 1KB OVERHEAD CARRY | L12: BW 1-ARM OVERHEAD SQUAT | O12: 1 KB DEADLIFT | R12: 1-LEG HINGE WITH MED/PEZZIBALL
B14: ANKLE ROCKER MOONWALK | E14: 1-LEG TOE STANCE | H14: LATERAL BOUND | L14: C-SKIP | O14: SPLIT SQUAT DROP & CATCH & JUMP | S14: SQUAT JUMPS
B15: =UnterkörperF!B15 -> Level F | G15: Block 2
G16: Datum 1 | H16: Woche 1 | J16: Datum 2 | L16: Datum 3 | M16: Woche 2 | O16: Datum 4 | Q16: Datum 5 | R16: Woche 3 | T16: Datum 6
B17: Explosiv Block | G17: TEMPO | H17: RPE | I17: SxR | J17: GEWICHT | L17: TEMPO | M17: RPE | N17: SxR | O17: GEWICHT | Q17: TEMPO | R17: RPE | S17: SxR | T17: GEWICHT
B18: 1 | C18: REACTIVE CMJ | G18: EXPL | I18: 3x5 | J18: BW | L18: EXPL | N18: 3x5 | O18: BW | Q18: EXPL | S18: 3x5 | T18: BW
B19: 2 | C19: 1-LEG BASKETBALL OH THROW INTO WALL | G19: EXPL | I19: 3x5 | J19: BB | L19: EXPL | N19: 3x5 | O19: BB | Q19: EXPL | S19: 3x5 | T19: BB
B20: 3 | C20: 1-LEG BASKETBALL CHEST PASSES INTO WALL | G20: EXPL | I20: 3x5 | J20: BB | L20: EXPL | N20: 3x5 | O20: BB | Q20: EXPL | S20: 3x5 | T20: BB
B22: Kraft Block (OKK) | G22: GEWICHT | H22: RPE | I22: SxR | J22: GEWICHT | L22: =G22 -> GEWICHT | M22: RPE | N22: SxR | O22: GEWICHT | Q22: =L22 -> GEWICHT | R22: RPE | S22: SxR | T22: GEWICHT
B23: 1 | C23: PUSH UP | H23: 8-9 | I23: 1x10 | M23: 8-9 | N23: =I23 -> 1x10 | R23: 8-9 | S23: =N23 -> 1x10
B24: 2 | C24: BAND SUPPORTED PULL UP | H24: 8-9 | I24: 1x8 | M24: 8-9 | N24: =I24 -> 1x8 | R24: 8-9 | S24: =N24 -> 1x8
B25: 3 | C25: PUSH UP PLANK TENNISBALL CATCH | H25: 8-9 | I25: 1x10ea | M25: 8-9 | N25: =I25 -> 1x10ea | R25: 8-9 | S25: =N25 -> 1x10ea
B26: 4 | C26: 3-POINT HINGE ROW | H26: 8-9 | I26: 1x20 | M26: 8-9 | N26: =I26 -> 1x20 | R26: 8-9 | S26: 1x20
B27: 5 | C27: STANDING 1-ARM OVERHEAD PRESS | H27: 8-9 | I27: 1x20/ea | M27: 8-9 | N27: =I27 -> 1x20/ea | R27: 8-9 | S27: =I27 -> 1x20/ea
B28: 6 | C28: FT ELEVATED SIDE PLANK - BLACKROLL | H28: 8-9 | I28: 3x10s/ea | M28: 8-9 | N28: =I28 -> 3x10s/ea | R28: 8-9 | S28: =N28 -> 3x10s/ea
B29: 7 | C29: PRONE "T", "V" RAISE | H29: 8-9 | I29: 1x20 | M29: 8-9 | N29: =I29 -> 1x20 | R29: 8-9 | S29: =N29 -> 1x20
B30: 8 | C30: STANDING BB BICEP CURL | H30: 8-9 | I30: 1x20 | M30: 8-9 | N30: =I30 -> 1x20 | R30: 8-9 | S30: =N30 -> 1x20
B31: 9 | C31: SUPPORTED DIPS | H31: 8-9 | I31: 1x20 | M31: 8-9 | N31: =I31 -> 1x20 | R31: 8-9 | S31: =N31 -> 1x20
B32: 10 | C32: LATERAL PUSH UP CRAWL | H32: 8-9 | I32: 1x10m | M32: 8-9 | N32: 1x12m | R32: 8-9 | S32: 1x15m
B33: 11 | C33: LOADED ARM SUPINATION/PRONATION | H33: 8-9 | I33: 1x20/ea | M33: 8-9 | N33: =I33 -> 1x20/ea | R33: 8-9 | S33: =N33 -> 1x20/ea
B34: 12 | C34: FLEXBAR BREAKING UP | H34: 8-9 | I34: 1x20/ea | M34: 8-9 | N34: =I34 -> 1x20/ea | R34: 8-9 | S34: =N34 -> 1x20/ea
B35: Halteübungen 2
B36: 13 | C36: ISO HOLD FT ELEVATED PUSH UP PLANK | H36: 8-9 | I36: 1x60s | M36: 8-9 | N36: 1x60s | R36: 8-9 | S36: =N36 -> 1x60s
B37: 14 | C37: ISO HOLD PULL UP ACTIVE LOW | H37: 8-9 | I37: 1x60s | M37: =H37 -> 8-9 | N37: =I37 -> 1x60s | R37: =M37 -> 8-9 | S37: =N37 -> 1x60s
B38: 15 | C38: ISO HOLD PRONE BENCH "V" | H38: 8-9 | I38: 1x60s | M38: 8-9 | N38: =I38 -> 1x60s | R38: 8-9 | S38: =N36 -> 1x60s
B39: 16 | C39: ISO HOLD 1/2 KN 1-ARM LANDMINE OVERHEAD PRESS | H39: 8-9 | I39: 1x60s/ea | M39: 8-9 | N39: =I39 -> 1x60s/ea | R39: 8-9 | S39: =I39 -> 1x60s/ea
V40: 1x15s
V41: 1x20s
V42: 1x25s
V43: 1x30s
V44: 1x45s
V45: 1x60s
V46: 1x8
V47: 1x10
V48: 3x10s
...

Sheet Unterkörper1
E2: Körperkonstitution | O2: Logo
C3: Unterkörper
E4: Größe
C5: NAME | E5: Gewicht
C10: Preparatory | E10: General Preparation | I10: Technical Development | N10: Accumulation | Q10: Dynamic | S10: 2x12
B12: Bewegungshygiene 1 (BH1)
B13: TGU - BEND TO 1/2-KN. | E13: LOADED FOOT HAND CRAWL | G13: 1KB SUITCASE CARRY | J13: KB/BW GOBLET SQUAT | N13: 1-ARM 1KB SUMO DEADLIFT | R13: LANDMINE 1-LEG DEADLIFT TO BOX
B14: Bewegungshygiene 2 (BH2)
B15: ANKLE ROCKER 1-LEG SQUAT | E15: ANKLE POS. 1 15 SEC | G15: LOADED ANKLE MARCH | J15: LATERAL SKIP | N15: 1-LEG MEDIAL HOP - TO BOX (NCM) | R15: LOADED SQUAT JUMP TO BOX
B17: LEVEL 1 | G17: Block 1
G18: Datum 1 | H18: Woche 1 | J18: Datum 2 | L18: Datum 3 | M18: Woche 2 | O18: Datum 4 | Q18: Datum 5 | R18: Woche 3 | T18: Datum 6
B19: Explosiv Block | G19: GEWICHT | H19: TEMPO | I19: SxR | J19: GEWICHT | L19: TEMPO | M19: RPE | N19: SxR | O19: GEWICHT | Q19: TEMPO | R19: RPE | S19: SxR | T19: GEWICHT
B20: 1 | C20: RESISTED ANKLE JUMPS | H20: EXPL | I20: 3x5 | J20: BW | L20: EXPL | N20: 3x5 | O20: BW | Q20: EXPL | S20: 3x5 | T20: BW
B21: 2 | C21: 1-LEG MEDBALL SIDE TOSS - PARALLEL | H21: EXPL | I21: 3x5 | J21: 2kg | L21: EXPL | N21: 3x5 | O21: =J21 -> 2kg | Q21: EXPL | S21: 3x5 | T21: =J21 -> 2kg
B22: 3 | C22: 1-LEG MEDBALL SIDE TOSS - 90° | H22: EXPL | I22: 3x5 | J22: 2kg | L22: EXPL | N22: 3x5 | O22: =J22 -> 2kg | Q22: EXPL | S22: 3x5 | T22: =J22 -> 2kg
B24: Kraft Block (UKK) | G24: GEWICHT | H24: TEMPO | I24: SxR/RPE 8-9 | J24: GEWICHT | L24: =G24 -> GEWICHT | M24: TEMPO | N24: =I24 -> SxR/RPE 8-9 | O24: GEWICHT | Q24: =L24 -> GEWICHT | R24: TEMPO | S24: =I24 -> SxR/RPE 8-9 | T24: GEWICHT
B25: 1 | C25: KB GOBLET SQUAT | H25: 3-1-1-0 | I25: 1x20 | M25: =H25 -> 3-1-1-0 | N25: =I25 -> 1x20 | R25: =M25 -> 3-1-1-0 | S25: =N25 -> 1x20
B26: 2 | C26: LOADED 2-LEG GLUTE BRIDGE | H26: 3-1-1-0 | I26: 1x20 | M26: =H26 -> 3-1-1-0 | N26: =I26 -> 1x20 | R26: =M26 -> 3-1-1-0 | S26: =N26 -> 1x20
B27: 3 | C27: PLANK - SANDBAG PULL THROUGH | H27: ISO | I27: 1x20 | M27: =H27 -> ISO | N27: =I27 -> 1x20 | R27: =H27 -> ISO | S27: =N27 -> 1x20
B29: 4 | C29: 1 KB DEADLIFT | H29: 3-1-1-0 | I29: 1x20 | M29: =H29 -> 3-1-1-0 | N29: =I29 -> 1x20 | R29: =H29 -> 3-1-1-0 | S29: =N29 -> 1x20
B30: 5 | C30: KB GOBLET SPLIT SQUAT | H30: 3-1-1-1 | I30: 1x20 | M30: =H30 -> 3-1-1-1 | N30: =I30 -> 1x20 | R30: =H29 -> 3-1-1-0 | S30: =N30 -> 1x20
B31: 6 | C31: FT ELEVATED SIDE PLANK - BLACKROLL | H31: 2-1-1-0 | I31: 3x10s ea | M31: =H31 -> 2-1-1-0 | N31: =I31 -> 3x10s ea | R31: =H31 -> 2-1-1-0 | S31: =N31 -> 3x10s ea
B33: Kraft Block (Ukp) | G33: GEWICHT | H33: TEMPO | I33: SxR/RPE 8-9 | J33: GEWICHT | L33: GEWICHT | M33: TEMPO | N33: =I33 -> SxR/RPE 8-9 | O33: GEWICHT | Q33: GEWICHT | R33: TEMPO | S33: =I33 -> SxR/RPE 8-9 | T33: GEWICHT
B34: 7 | C34: CROSS STEP UP HIGH STEPPER | H34: 3-1-1-1 | I34: 1x20 | M34: =H34 -> 3-1-1-1 | N34: =I34 -> 1x20 | R34: =H34 -> 3-1-1-1 | S34: =I34 -> 1x20
B35: 8 | C35: 1/2-KN ANTIROTATION HOLD - BAND | H35: ISO | I35: 3x10s ea | M35: =H35 -> ISO | N35: =I35 -> 3x10s ea | R35: =H35 -> ISO | S35: =N35 -> 3x10s ea
B36: 9 | C36: STANDING MINIBAND HIP EXTERNAL ROTATION | H36: 2-1-1-0 | I36: 1x20 | M36: =H36 -> 2-1-1-0 | N36: =I36 -> 1x20 | R36: =H36 -> 2-1-1-0 | S36: =N36 -> 1x20
B38: 10 | C38: SIDE MARCH WITH MINIBAND OVER KNEE | H38: 3-1-1-1 | I38: 1x20 | M38: =H38 -> 3-1-1-1 | N38: =I38 -> 1x20 | R38: =H38 -> 3-1-1-1 | S38: =N38 -> 1x20
B39: 11 | C39: LOADED FOOT COPENHAGEN PLANK BLACKROLL | H39: ISO | I39: 3x10s ea | M39: =H39 -> ISO | N39: =I39 -> 3x10s ea | R39: =H39 -> ISO | S39: =N39 -> 3x10s ea
B40: 12 | C40: TIBIALIS WALL RAISES | H40: 3-1-1-0 | I40: 1x20 | M40: =H40 -> 3-1-1-0 | N40: =I40 -> 1x20 | R40: =H40 -> 3-1-1-0 | S40: =N40 -> 1x20
B42: Halteübungen (Ukiso) | G42: GEWICHT | H42: TEMPO | I42: SxR/RPE 9 | J42: GEWICHT | L42: =G42 -> GEWICHT | M42: TEMPO | N42: =I42 -> SxR/RPE 9 | O42: GEWICHT | Q42: =L42 -> GEWICHT | R42: TEMPO | S42: =I42 -> SxR/RPE 9 | T42: GEWICHT
B43: 13 | C43: ISO HOLD 1-LEG CALF RAISE | H43: ISO | I43: 1x30s | M43: =H43 -> ISO | N43: =I43 -> 1x30s | R43: =H43 -> ISO | S43: =N43 -> 1x30s
B44: 14 | C44: ISO HOLD SPLIT SQUAT | H44: ISO | I44: 1x30s | M44: =H43 -> ISO | N44: =I44 -> 1x30s | R44: =H43 -> ISO | S44: =N44 -> 1x30s
B45: 15 | C45: 1-LEG HAMSTRING BRIDGE | H45: ISO | I45: 1x30s | M45: =H43 -> ISO | N45: =I45 -> 1x30s | R45: =H43 -> ISO | S45: =N45 -> 1x30s

Sheet Oberkörper1
E2: Körperkonstitution | O2: Logo
C3: Oberkörper
E4: Größe
C5: NAME | E5: Gewicht
C10: Preparatory | E10: General Preparation | I10: Technical Development | M10: Accumulation | Q10: Dynamic | S10: 2x12
B12: Bewegungshygiene 1 (BH1)
B13: =Unterkörper1!B13 -> TGU - BEND TO 1/2-KN. | E13: =Unterkörper1!E13 -> LOADED FOOT HAND CRAWL | G13: =Unterkörper1!G13 -> 1KB SUITCASE CARRY | J13: =Unterkörper1!J13 -> KB/BW GOBLET SQUAT | N13: =Unterkörper1!N13 -> 1-ARM 1KB SUMO DEADLIFT | R13: =Unterkörper1!R13 -> LANDMINE 1-LEG DEADLIFT TO BOX
B14: Bewegungshygiene 2 (BH2)
B15: =Unterkörper1!B15 -> ANKLE ROCKER 1-LEG SQUAT | E15: =Unterkörper1!E15 -> ANKLE POS. 1 15 SEC | G15: =Unterkörper1!G15 -> LOADED ANKLE MARCH | J15: =Unterkörper1!J15 -> LATERAL SKIP | N15: =Unterkörper1!N15 -> 1-LEG MEDIAL HOP - TO BOX (NCM) | R15: =Unterkörper1!R15 -> LOADED SQUAT JUMP TO BOX
B16: =Unterkörper1!B17 -> LEVEL 1 | G16: Block 2
G17: Datum 1 | H17: Woche 1 | J17: Datum 2 | L17: Datum 3 | M17: Woche 2 | O17: Datum 4 | Q17: Datum 5 | R17: Woche 3 | T17: Datum 6
B18: Explosiv Block | G18: GEWICHT | H18: TEMPO | I18: SxR | J18: GEWICHT | L18: GEWICHT | M18: TEMPO | N18: SxR | O18: GEWICHT | Q18: GEWICHT | R18: TEMPO | S18: SxR | T18: GEWICHT
B19: 1 | C19: REACTIVE BOX SQUAT JUMP | H19: EXPL | I19: 3x5 | J19: BW | M19: =H19 -> EXPL | N19: 3x5 | O19: BW | R19: =H19 -> EXPL | S19: 3x5 | T19: BW
B20: 2 | C20: 1/2-KN MB OH THROW & CATCH | H20: EXPL | I20: 3x5 | J20: 1kg | M20: =H20 -> EXPL | N20: 3x5 | O20: =J20 -> 1kg | R20: =H20 -> EXPL | S20: 3x5 | T20: =J20 -> 1kg
B21: 3 | C21: 1/2-KN MB CHEST PASS & CATCH | H21: EXPL | I21: 3x5 | J21: 1kg | M21: =H21 -> EXPL | N21: 3x5 | O21: =J21 -> 1kg | R21: =H21 -> EXPL | S21: 3x5 | T21: =J21 -> 1kg
B23: Kraft Block (OKK) | G23: GEWICHT | H23: TEMPO | I23: SxR/RPE 7-8 | J23: GEWICHT | L23: =G23 -> GEWICHT | M23: TEMPO | N23: =I23 -> SxR/RPE 7-8 | O23: GEWICHT | Q23: =L23 -> GEWICHT | R23: TEMPO | S23: =I23 -> SxR/RPE 7-8 | T23: GEWICHT
B24: 1 | C24: 1/2-KN 1-ARM CABLE/BAND PRESS | H24: 2-1-1-0 | I24: 1x20 | M24: =H24 -> 2-1-1-0 | N24: =I24 -> 1x20 | R24: =H24 -> 2-1-1-0 | S24: =I24 -> 1x20
B25: 2 | C25: 1/2-KN 1-ARM BAND PULLDOWN | H25: 2-1-1-0 | I25: 1x20 | M25: =H25 -> 2-1-1-0 | N25: =I25 -> 1x20 | R25: =H25 -> 2-1-1-0 | S25: =I25 -> 1x20
B26: 3 | C26: LOADED FOOT HAND CRAWL | H26: 1-1-1-1 | I26: 2x15m | N26: =I26 -> 2x15m | S26: =I26 -> 2x15m
B28: 4 | C28: STANDING 1-ARM BAND/CABLE ROW | H28: 2-1-1-0 | I28: 1x20 | M28: =H28 -> 2-1-1-0 | N28: =I28 -> 1x20 | R28: =H28 -> 2-1-1-0 | S28: =I28 -> 1x20
B29: 5 | C29: 1/2 KN 1-ARM OVERHEAD PRESS | H29: 2-1-1-0 | I29: 1x20 | M29: =H29 -> 2-1-1-0 | N29: =I29 -> 1x20 | R29: =H29 -> 2-1-1-0 | S29: =I29 -> 1x20
B30: 6 | C30: PLANK - SWITCH ON BACK | H30: ISO | I30: 1x20 | M30: =H30 -> ISO | N30: =I30 -> 1x20 | R30: =H30 -> ISO | S30: =I30 -> 1x20
B32: Kraft Block (Okp) | G32: GEWICHT | H32: TEMPO | I32: SxR/RPE 8-9 | J32: GEWICHT | L32: GEWICHT | M32: TEMPO | N32: =I32 -> SxR/RPE 8-9 | O32: GEWICHT | Q32: GEWICHT | R32: TEMPO | S32: =I32 -> SxR/RPE 8-9 | T32: GEWICHT
B33: 7 | C33: STANDING BB BICEP CURL | H33: 2-1-1-0 | I33: 1x20 | M33: =H33 -> 2-1-1-0 | N33: =I33 -> 1x20 | R33: =H33 -> 2-1-1-0 | S33: =I33 -> 1x20
B34: 8 | C34: STANDING BAND/CABLE TRICEP CURL | H34: 2-1-1-0 | I34: 1x20 | M34: =H34 -> 2-1-1-0 | N34: =I34 -> 1x20 | R34: =H34 -> 2-1-1-0 | S34: =I34 -> 1x20
B35: 9 | C35: FT ELEVATED SIDE PLANK - BLACKROLL | H35: ISO | I35: 3x10s ea | M35: =H35 -> ISO | N35: =I35 -> 3x10s ea | R35: =H35 -> ISO | S35: =I35 -> 3x10s ea
B37: 10 | C37: LOADED ARM SUPINATION/PRONATION | H37: 2-1-1-0 | I37: 1x20 | M37: =H37 -> 2-1-1-0 | N37: =I37 -> 1x20 | R37: =H37 -> 2-1-1-0 | S37: =I37 -> 1x20
B38: 11 | C38: FLEXBAR WRING VERTICAL | H38: 5-0-3-0 | I38: 1x20 | M38: =H38 -> 5-0-3-0 | N38: =I38 -> 1x20 | R38: =H38 -> 5-0-3-0 | S38: =I38 -> 1x20
B39: 12 | C39: STANDING BAND PULL APART | H39: 3-1-1-1 | I39: 1x20 | M39: =H39 -> 3-1-1-1 | N39: =I39 -> 1x20 | R39: =H39 -> 3-1-1-1 | S39: =I39 -> 1x20
B41: Halteübungen (Okiso) | G41: GEWICHT | H41: TEMPO | I41: SxR/RPE 9 | J41: GEWICHT | L41: =G41 -> GEWICHT | M41: TEMPO | N41: =I41 -> SxR/RPE 9 | O41: GEWICHT | Q41: =L41 -> GEWICHT | R41: TEMPO | S41: =I41 -> SxR/RPE 9 | T41: GEWICHT
B42: 13 | C42: PUSH UP PLANK | H42: ISO | I42: 1x30s | M42: =H42 -> ISO | N42: =I42 -> 1x30s | R42: =H42 -> ISO | S42: =N42 -> 1x30s
B43: 14 | C43: ISO HOLD PRONE BENCH "T" | H43: ISO | I43: 1x30s | M43: =H43 -> ISO | N43: =I43 -> 1x30s | R43: =H43 -> ISO | S43: =N43 -> 1x30s
B44: 15 | C44: 1/2-KN LANDMINE PRESS-ISO HOLD | H44: ISO | I44: 1x30s | M44: =H44 -> ISO | N44: =I44 -> 1x30s | R44: =H44 -> ISO | S44: =N44 -> 1x30s

Sheet Unterkörper2
E2: Körperkonstitution | O2: Logo
C3: Unterkörper
E4: Größe
C5: NAME | E5: Gewicht
C10: Preparatory | E10: General Preparation | I10: Technical Development | N10: Accumulation | Q10: Dynamic | S10: 2x12
B12: Bewegungshygiene 1 (BH1)
B13: TGU - 1/2-KN. TO STAND | E13: LOADED BKWD CRAWL | G13: 1KB 1-ARM RACK CARRY | J13: KB/BW GOBLET SQUAT | N13: 2KB SUITCASE DEADLIFT | R13: 1KB 1-LEG DEADLIFT TO BOX
B14: Bewegungshygiene 2 (BH2)
B15: LOADED ANKLE ROCKER PUSH PULL | E15: ANKLE POS. 1 30 SEC | G15: LOADED ANKLE SKIPS | J15: KNEE RUN | N15: 1-LEG LINEAR HOP - TO BOX (NCM) | R15: LOADED CMJ TO BOX
B17: LEVEL 2 | G17: Block 1
G18: Datum 1 | H18: Woche 1 | J18: Datum 2 | L18: Datum 3 | M18: Woche 2 | O18: Datum 4 | Q18: Datum 5 | R18: Woche 3 | T18: Datum 6
B19: Explosiv Block | G19: GEWICHT | H19: TEMPO | I19: SxR | J19: GEWICHT | L19: TEMPO | M19: RPE | N19: SxR | O19: GEWICHT | Q19: TEMPO | R19: RPE | S19: SxR | T19: GEWICHT
B20: 1 | C20: ASSISTED ANKLE JUMPS | H20: EXPL | I20: 3x5 | J20: BW | L20: EXPL | N20: 3x5 | O20: BW | Q20: EXPL | S20: 3x5 | T20: BW
B21: 2 | C21: SPLIT SQUAT MEDBALL SIDE TOSS AND CATCH - PARALLEL | H21: EXPL | I21: 3x5 | J21: 2kg | L21: EXPL | N21: 3x5 | O21: =J21 -> 2kg | Q21: EXPL | S21: 3x5 | T21: =J21 -> 2kg
B22: 3 | C22: SPLIT SQUAT MEDBALL SIDE TOSS AND CATCH - 90° | H22: EXPL | I22: 3x5 | J22: 2kg | L22: EXPL | N22: 3x5 | O22: =J22 -> 2kg | Q22: EXPL | S22: 3x5 | T22: =J22 -> 2kg
B24: Kraft Block (UKK) | G24: GEWICHT | H24: TEMPO | I24: SxR/RPE 8-9 | J24: GEWICHT | L24: =G24 -> GEWICHT | M24: TEMPO | N24: =I24 -> SxR/RPE 8-9 | O24: GEWICHT | Q24: =L24 -> GEWICHT | R24: TEMPO | S24: =I24 -> SxR/RPE 8-9 | T24: GEWICHT
B25: 1 | C25: BW RACK SQUAT | H25: 3-1-1-0 | I25: 1x15 | M25: =H25 -> 3-1-1-0 | N25: =I25 -> 1x15 | R25: =M25 -> 3-1-1-0 | S25: =N25 -> 1x15
B26: 2 | C26: LOADED 1-LEG GLUTE BRIDGE | H26: 3-1-1-1 | I26: 1x15 | M26: =H26 -> 3-1-1-1 | N26: =I26 -> 1x15 | R26: =M26 -> 3-1-1-1 | S26: =N26 -> 1x15
B27: 3 | C27: PUSH UP PLANK SHOULDER TAP AND TENNISBALL CATCH | H27: ISO | I27: 1x15 | M27: =H27 -> ISO | N27: =I27 -> 1x15 | R27: =H27 -> ISO | S27: =N27 -> 1x15
B29: 4 | C29: 1 KB DEADLIFT | H29: 3-1-1-0 | I29: 1x15 | M29: =H29 -> 3-1-1-0 | N29: =I29 -> 1x15 | R29: =H29 -> 3-1-1-0 | S29: =N29 -> 1x15
B30: 5 | C30: 2 KB SUITCASE SPLIT SQUAT | H30: 3-1-1-1 | I30: 1x15 | M30: =H30 -> 3-1-1-1 | N30: =I30 -> 1x15 | R30: =H29 -> 3-1-1-0 | S30: =N30 -> 1x15
B31: 6 | C31: BENCH OBLIQUE ISO HOLD - CHEST | H31: ISO | I31: 3x10s ea | M31: =H31 -> ISO | N31: =I31 -> 3x10s ea | R31: =H31 -> ISO | S31: =N31 -> 3x10s ea
B33: Kraft Block (Ukp) | G33: GEWICHT | H33: TEMPO | I33: SxR/RPE 8-9 | J33: GEWICHT | L33: GEWICHT | M33: TEMPO | N33: =I33 -> SxR/RPE 8-9 | O33: GEWICHT | Q33: GEWICHT | R33: TEMPO | S33: =I33 -> SxR/RPE 8-9 | T33: GEWICHT
B34: 7 | C34: STEPDOWN MEDIUM STEPPER | H34: 3-1-1-1 | I34: 1x15 | M34: =H34 -> 3-1-1-1 | N34: =I34 -> 1x15 | R34: =H34 -> 3-1-1-1 | S34: =I34 -> 1x15
B35: 8 | C35: 1/2-KN ANTI-ROTATION PRESS | H35: 2-2-2-2 | I35: 3x5 ea | M35: =H35 -> 2-2-2-2 | N35: =I35 -> 3x5 ea | R35: =H35 -> 2-2-2-2 | S35: =N35 -> 3x5 ea
